Workbook

Sheet 📊 Dashboard
A1: 📊 QA DASHBOARD — PROFIX PHASE 1
A3: Sheet Name | B3: Total TCs | C3: ✅ Passed | D3: ❌ Failed | E3: 🟠 Blocked | F3: Doing | G3: Pass Rate (%)
A4: II.5.1.1.2 | B4: =COUNTA('II.5.1.1.2'!A:A)-2 | C4: =COUNTIF('II.5.1.1.2'!U:U,"Pass") | D4: =COUNTIF('II.5.1.1.2'!U:U,"Fail") | E4: =COUNTIF('II.5.1.1.2'!U:U,"Blocked") | F4: =COUNTIF('II.5.1.1.2'!U:U,"Doing") | G4: =IFERROR(ROUND(C4/B4*100,1),0)
A5: II.5.1.1.3 | B5: =COUNTA('II.5.1.1.3'!A:A)-2 | C5: =COUNTIF('II.5.1.1.3'!U:U,"Pass") | D5: =COUNTIF('II.5.1.1.3'!U:U,"Fail") | E5: =COUNTIF('II.5.1.1.3'!U:U,"Blocked") | F5: =COUNTIF('II.5.1.1.3'!U:U,"Doing") | G5: =IFERROR(ROUND(C5/B5*100,1),0)
A6: II.5.1.1.4 | B6: =COUNTA('II.5.1.1.4'!A:A)-2 | C6: =COUNTIF('II.5.1.1.4'!U:U,"Pass") | D6: =COUNTIF('II.5.1.1.4'!U:U,"Fail") | E6: =COUNTIF('II.5.1.1.4'!U:U,"Blocked") | F6: =COUNTIF('II.5.1.1.4'!U:U,"Doing") | G6: =IFERROR(ROUND(C6/B6*100,1),0)
A7: II.5.1.1.5 | B7: =COUNTA('II.5.1.1.5'!A:A)-2 | C7: =COUNTIF('II.5.1.1.5'!U:U,"Pass") | D7: =COUNTIF('II.5.1.1.5'!U:U,"Fail") | E7: =COUNTIF('II.5.1.1.5'!U:U,"Blocked") | F7: =COUNTIF('II.5.1.1.5'!U:U,"Doing") | G7: =IFERROR(ROUND(C7/B7*100,1),0)
A8: II.5.1.1.6 | B8: =COUNTA('II.5.1.1.6'!A:A)-2 | C8: =COUNTIF('II.5.1.1.6'!U:U,"Pass") | D8: =COUNTIF('II.5.1.1.6'!U:U,"Fail") | E8: =COUNTIF('II.5.1.1.6'!U:U,"Blocked") | F8: =COUNTIF('II.5.1.1.6'!U:U,"Doing") | G8: =IFERROR(ROUND(C8/B8*100,1),0)
A9: II.5.1.2 | B9: =COUNTA('II.5.1.2'!A:A)-2 | C9: =COUNTIF('II.5.1.2'!U:U,"Pass") | D9: =COUNTIF('II.5.1.2'!U:U,"Fail") | E9: =COUNTIF('II.5.1.2'!U:U,"Blocked") | F9: =COUNTIF('II.5.1.2'!U:U,"Doing") | G9: =IFERROR(ROUND(C9/B9*100,1),0)
A10: II.5.1.3 | B10: =COUNTA('II.5.1.3'!A:A)-2 | C10: =COUNTIF('II.5.1.3'!U:U,"Pass") | D10: =COUNTIF('II.5.1.3'!U:U,"Fail") | E10: =COUNTIF('II.5.1.3'!U:U,"Blocked") | F10: =COUNTIF('II.5.1.3'!U:U,"Doing") | G10: =IFERROR(ROUND(C10/B10*100,1),0)
A11: II.5.1.4 | B11: =COUNTA('II.5.1.4'!A:A)-2 | C11: =COUNTIF('II.5.1.4'!U:U,"Pass") | D11: =COUNTIF('II.5.1.4'!U:U,"Fail") | E11: =COUNTIF('II.5.1.4'!U:U,"Blocked") | F11: =COUNTIF('II.5.1.4'!U:U,"Doing") | G11: =IFERROR(ROUND(C11/B11*100,1),0)

Sheet 📅 Daily Tracking
A1: 📅 DAILY TEST TRACKING — PROFIX PHASE 1 (TC Executed per Day)
A2: Ngày | B2: Tổng TC Executed | C2: Định | D2: Thanh | E2: Vân Anh | F2: .... | G2: Note
A3: 💡 Hướng dẫn: Tester điền tên vào cột P (Tester) và ngày vào cột Q (Exec Date) ở mỗi TC sheet. Sheet này sẽ tự động đếm theo COUNTIFS.
A4: 18/03 | B4: =COUNTIF('[1]🧪 TC_PR01'!Q:Q,"18/03")+COUNTIF('[2]🧪 TC_PR02'!Q:Q,"18/03")+COUNTIF('[3]🧪 TC_OT01'!Q:Q,"18/03")+COUNTIF('[4]🧪 TC_SA'!Q:Q,"18/03")+COUNTIF('[5]🧪 TC_SE'!Q:Q,"18/03")+COUNTIF('[6]🧪 TC_RP'!Q:Q,"18/03") | C4: =COUNTIFS('[1]🧪 TC_PR01'!P:P,"Định",'[1]🧪 TC_PR01'!Q:Q,"18/03")+COUNTIFS('[2]🧪 TC_PR02'!P:P,"Định",'[2]🧪 TC_PR02'!Q:Q,"18/03")+COUNTIFS('[3]🧪 TC_OT01'!P:P,"Định",'[3]🧪 TC_OT01'!Q:Q,"18/03")+COUNTIFS('[4]🧪 TC_SA'!P:P,"Định",'[4]🧪 TC_SA'!Q:Q,"18/03")+COUNTIFS('[5]🧪 TC_SE'!P:P,"Định",'[5]🧪 TC_SE'!Q:Q,"18/03")+COUNTIFS('[6]🧪 TC_RP'!P:P,"Định",'[6]🧪 TC_RP'!Q:Q,"18/03") | D4: =COUNTIFS('[1]🧪 TC_PR01'!P:P,"Thanh",'[1]🧪 TC_PR01'!Q:Q,"18/03")+COUNTIFS('[2]🧪 TC_PR02'!P:P,"Thanh",'[2]🧪 TC_PR02'!Q:Q,"18/03")+COUNTIFS('[3]🧪 TC_OT01'!P:P,"Thanh",'[3]🧪 TC_OT01'!Q:Q,"18/03")+COUNTIFS('[4]🧪 TC_SA'!P:P,"Thanh",'[4]🧪 TC_SA'!Q:Q,"18/03")+COUNTIFS('[5]🧪 TC_SE'!P:P,"Thanh",'[5]🧪 TC_SE'!Q:Q,"18/03")+COUNTIFS('[6]🧪 TC_RP'!P:P,"Thanh",'[6]🧪 TC_RP'!Q:Q,"18/03") | E4: =COUNTIFS('[1]🧪 TC_PR01'!P:P,"Vân Anh",'[1]🧪 TC_PR01'!Q:Q,"18/03")+COUNTIFS('[2]🧪 TC_PR02'!P:P,"Vân Anh",'[2]🧪 TC_PR02'!Q:Q,"18/03")+COUNTIFS('[3]🧪 TC_OT01'!P:P,"Vân Anh",'[3]🧪 TC_OT01'!Q:Q,"18/03")+COUNTIFS('[4]🧪 TC_SA'!P:P,"Vân Anh",'[4]🧪 TC_SA'!Q:Q,"18/03")+COUNTIFS('[5]🧪 TC_SE'!P:P,"Vân Anh",'[5]🧪 TC_SE'!Q:Q,"18/03")+COUNTIFS('[6]🧪 TC_RP'!P:P,"Vân Anh",'[6]🧪 TC_RP'!Q:Q,"18/03") | F4: =COUNTIFS('[1]🧪 TC_PR01'!P:P,"Hiệp",'[1]🧪 TC_PR01'!Q:Q,"18/03")+COUNTIFS('[2]🧪 TC_PR02'!P:P,"Hiệp",'[2]🧪 TC_PR02'!Q:Q,"18/03")+COUNTIFS('[3]🧪 TC_OT01'!P:P,"Hiệp",'[3]🧪 TC_OT01'!Q:Q,"18/03")+COUNTIFS('[4]🧪 TC_SA'!P:P,"Hiệp",'[4]🧪 TC_SA'!Q:Q,"18/03")+COUNTIFS('[5]🧪 TC_SE'!P:P,"Hiệp",'[5]🧪 TC_SE'!Q:Q,"18/03")+COUNTIFS('[6]🧪 TC_RP'!P:P,"Hiệp",'[6]🧪 TC_RP'!Q:Q,"18/03")
A5: 19/03 | B5: =COUNTIF('[1]🧪 TC_PR01'!Q:Q,"19/03")+COUNTIF('[2]🧪 TC_PR02'!Q:Q,"19/03")+COUNTIF('[3]🧪 TC_OT01'!Q:Q,"19/03")+COUNTIF('[4]🧪 TC_SA'!Q:Q,"19/03")+COUNTIF('[5]🧪 TC_SE'!Q:Q,"19/03")+COUNTIF('[6]🧪 TC_RP'!Q:Q,"19/03") | C5: =COUNTIFS('[1]🧪 TC_PR01'!P:P,"Định",'[1]🧪 TC_PR01'!Q:Q,"19/03")+COUNTIFS('[2]🧪 TC_PR02'!P:P,"Định",'[2]🧪 TC_PR02'!Q:Q,"19/03")+COUNTIFS('[3]🧪 TC_OT01'!P:P,"Định",'[3]🧪 TC_OT01'!Q:Q,"19/03")+COUNTIFS('[4]🧪 TC_SA'!P:P,"Định",'[4]🧪 TC_SA'!Q:Q,"19/03")+COUNTIFS('[5]🧪 TC_SE'!P:P,"Định",'[5]🧪 TC_SE'!Q:Q,"19/03")+COUNTIFS('[6]🧪 TC_RP'!P:P,"Định",'[6]🧪 TC_RP'!Q:Q,"19/03") | D5: =COUNTIFS('[1]🧪 TC_PR01'!P:P,"Thanh",'[1]🧪 TC_PR01'!Q:Q,"19/03")+COUNTIFS('[2]🧪 TC_PR02'!P:P,"Thanh",'[2]🧪 TC_PR02'!Q:Q,"19/03")+COUNTIFS('[3]🧪 TC_OT01'!P:P,"Thanh",'[3]🧪 TC_OT01'!Q:Q,"19/03")+COUNTIFS('[4]🧪 TC_SA'!P:P,"Thanh",'[4]🧪 TC_SA'!Q:Q,"19/03")+COUNTIFS('[5]🧪 TC_SE'!P:P,"Thanh",'[5]🧪 TC_SE'!Q:Q,"19/03")+COUNTIFS('[6]🧪 TC_RP'!P:P,"Thanh",'[6]🧪 TC_RP'!Q:Q,"19/03") | E5: =COUNTIFS('[1]🧪 TC_PR01'!P:P,"Vân Anh",'[1]🧪 TC_PR01'!Q:Q,"19/03")+COUNTIFS('[2]🧪 TC_PR02'!P:P,"Vân Anh",'[2]🧪 TC_PR02'!Q:Q,"19/03")+COUNTIFS('[3]🧪 TC_OT01'!P:P,"Vân Anh",'[3]🧪 TC_OT01'!Q:Q,"19/03")+COUNTIFS('[4]🧪 TC_SA'!P:P,"Vân Anh",'[4]🧪 TC_SA'!Q:Q,"19/03")+COUNTIFS('[5]🧪 TC_SE'!P:P,"Vân Anh",'[5]🧪 TC_SE'!Q:Q,"19/03")+COUNTIFS('[6]🧪 TC_RP'!P:P,"Vân Anh",'[6]🧪 TC_RP'!Q:Q,"19/03") | F5: =COUNTIFS('[1]🧪 TC_PR01'!P:P,"Hiệp",'[1]🧪 TC_PR01'!Q:Q,"19/03")+COUNTIFS('[2]🧪 TC_PR02'!P:P,"Hiệp",'[2]🧪 TC_PR02'!Q:Q,"19/03")+COUNTIFS('[3]🧪 TC_OT01'!P:P,"Hiệp",'[3]🧪 TC_OT01'!Q:Q,"19/03")+COUNTIFS('[4]🧪 TC_SA'!P:P,"Hiệp",'[4]🧪 TC_SA'!Q:Q,"19/03")+COUNTIFS('[5]🧪 TC_SE'!P:P,"Hiệp",'[5]🧪 TC_SE'!Q:Q,"19/03")+COUNTIFS('[6]🧪 TC_RP'!P:P,"Hiệp",'[6]🧪 TC_RP'!Q:Q,"19/03")
A6: 20/03 | B6: =COUNTIF('[1]🧪 TC_PR01'!Q:Q,"20/03")+COUNTIF('[2]🧪 TC_PR02'!Q:Q,"20/03")+COUNTIF('[3]🧪 TC_OT01'!Q:Q,"20/03")+COUNTIF('[4]🧪 TC_SA'!Q:Q,"20/03")+COUNTIF('[5]🧪 TC_SE'!Q:Q,"20/03")+COUNTIF('[6]🧪 TC_RP'!Q:Q,"20/03") | C6: =COUNTIFS('[1]🧪 TC_PR01'!P:P,"Định",'[1]🧪 TC_PR01'!Q:Q,"20/03")+COUNTIFS('[2]🧪 TC_PR02'!P:P,"Định",'[2]🧪 TC_PR02'!Q:Q,"20/03")+COUNTIFS('[3]🧪 TC_OT01'!P:P,"Định",'[3]🧪 TC_OT01'!Q:Q,"20/03")+COUNTIFS('[4]🧪 TC_SA'!P:P,"Định",'[4]🧪 TC_SA'!Q:Q,"20/03")+COUNTIFS('[5]🧪 TC_SE'!P:P,"Định",'[5]🧪 TC_SE'!Q:Q,"20/03")+COUNTIFS('[6]🧪 TC_RP'!P:P,"Định",'[6]🧪 TC_RP'!Q:Q,"20/03") | D6: =COUNTIFS('[1]🧪 TC_PR01'!P:P,"Thanh",'[1]🧪 TC_PR01'!Q:Q,"20/03")+COUNTIFS('[2]🧪 TC_PR02'!P:P,"Thanh",'[2]🧪 TC_PR02'!Q:Q,"20/03")+COUNTIFS('[3]🧪 TC_OT01'!P:P,"Thanh",'[3]🧪 TC_OT01'!Q:Q,"20/03")+COUNTIFS('[4]🧪 TC_SA'!P:P,"Thanh",'[4]🧪 TC_SA'!Q:Q,"20/03")+COUNTIFS('[5]🧪 TC_SE'!P:P,"Thanh",'[5]🧪 TC_SE'!Q:Q,"20/03")+COUNTIFS('[6]🧪 TC_RP'!P:P,"Thanh",'[6]🧪 TC_RP'!Q:Q,"20/03") | E6: =COUNTIFS('[1]🧪 TC_PR01'!P:P,"Vân Anh",'[1]🧪 TC_PR01'!Q:Q,"20/03")+COUNTIFS('[2]🧪 TC_PR02'!P:P,"Vân Anh",'[2]🧪 TC_PR02'!Q:Q,"20/03")+COUNTIFS('[3]🧪 TC_OT01'!P:P,"Vân Anh",'[3]🧪 TC_OT01'!Q:Q,"20/03")+COUNTIFS('[4]🧪 TC_SA'!P:P,"Vân Anh",'[4]🧪 TC_SA'!Q:Q,"20/03")+COUNTIFS('[5]🧪 TC_SE'!P:P,"Vân Anh",'[5]🧪 TC_SE'!Q:Q,"20/03")+COUNTIFS('[6]🧪 TC_RP'!P:P,"Vân Anh",'[6]🧪 TC_RP'!Q:Q,"20/03") | F6: =COUNTIFS('[1]🧪 TC_PR01'!P:P,"Hiệp",'[1]🧪 TC_PR01'!Q:Q,"20/03")+COUNTIFS('[2]🧪 TC_PR02'!P:P,"Hiệp",'[2]🧪 TC_PR02'!Q:Q,"20/03")+COUNTIFS('[3]🧪 TC_OT01'!P:P,"Hiệp",'[3]🧪 TC_OT01'!Q:Q,"20/03")+COUNTIFS('[4]🧪 TC_SA'!P:P,"Hiệp",'[4]🧪 TC_SA'!Q:Q,"20/03")+COUNTIFS('[5]🧪 TC_SE'!P:P,"Hiệp",'[5]🧪 TC_SE'!Q:Q,"20/03")+COUNTIFS('[6]🧪 TC_RP'!P:P,"Hiệp",'[6]🧪 TC_RP'!Q:Q,"20/03")
A7: 21/03 | B7: =COUNTIF('[1]🧪 TC_PR01'!Q:Q,"21/03")+COUNTIF('[2]🧪 TC_PR02'!Q:Q,"21/03")+COUNTIF('[3]🧪 TC_OT01'!Q:Q,"21/03")+COUNTIF('[4]🧪 TC_SA'!Q:Q,"21/03")+COUNTIF('[5]🧪 TC_SE'!Q:Q,"21/03")+COUNTIF('[6]🧪 TC_RP'!Q:Q,"21/03") | C7: =COUNTIFS('[1]🧪 TC_PR01'!P:P,"Định",'[1]🧪 TC_PR01'!Q:Q,"21/03")+COUNTIFS('[2]🧪 TC_PR02'!P:P,"Định",'[2]🧪 TC_PR02'!Q:Q,"21/03")+COUNTIFS('[3]🧪 TC_OT01'!P:P,"Định",'[3]🧪 TC_OT01'!Q:Q,"21/03")+COUNTIFS('[4]🧪 TC_SA'!P:P,"Định",'[4]🧪 TC_SA'!Q:Q,"21/03")+COUNTIFS('[5]🧪 TC_SE'!P:P,"Định",'[5]🧪 TC_SE'!Q:Q,"21/03")+COUNTIFS('[6]🧪 TC_RP'!P:P,"Định",'[6]🧪 TC_RP'!Q:Q,"21/03") | D7: =COUNTIFS('[1]🧪 TC_PR01'!P:P,"Thanh",'[1]🧪 TC_PR01'!Q:Q,"21/03")+COUNTIFS('[2]🧪 TC_PR02'!P:P,"Thanh",'[2]🧪 TC_PR02'!Q:Q,"21/03")+COUNTIFS('[3]🧪 TC_OT01'!P:P,"Thanh",'[3]🧪 TC_OT01'!Q:Q,"21/03")+COUNTIFS('[4]🧪 TC_SA'!P:P,"Thanh",'[4]🧪 TC_SA'!Q:Q,"21/03")+COUNTIFS('[5]🧪 TC_SE'!P:P,"Thanh",'[5]🧪 TC_SE'!Q:Q,"21/03")+COUNTIFS('[6]🧪 TC_RP'!P:P,"Thanh",'[6]🧪 TC_RP'!Q:Q,"21/03") | E7: =COUNTIFS('[1]🧪 TC_PR01'!P:P,"Vân Anh",'[1]🧪 TC_PR01'!Q:Q,"21/03")+COUNTIFS('[2]🧪 TC_PR02'!P:P,"Vân Anh",'[2]🧪 TC_PR02'!Q:Q,"21/03")+COUNTIFS('[3]🧪 TC_OT01'!P:P,"Vân Anh",'[3]🧪 TC_OT01'!Q:Q,"21/03")+COUNTIFS('[4]🧪 TC_SA'!P:P,"Vân Anh",'[4]🧪 TC_SA'!Q:Q,"21/03")+COUNTIFS('[5]🧪 TC_SE'!P:P,"Vân Anh",'[5]🧪 TC_SE'!Q:Q,"21/03")+COUNTIFS('[6]🧪 TC_RP'!P:P,"Vân Anh",'[6]🧪 TC_RP'!Q:Q,"21/03") | F7: =COUNTIFS('[1]🧪 TC_PR01'!P:P,"Hiệp",'[1]🧪 TC_PR01'!Q:Q,"21/03")+COUNTIFS('[2]🧪 TC_PR02'!P:P,"Hiệp",'[2]🧪 TC_PR02'!Q:Q,"21/03")+COUNTIFS('[3]🧪 TC_OT01'!P:P,"Hiệp",'[3]🧪 TC_OT01'!Q:Q,"21/03")+COUNTIFS('[4]🧪 TC_SA'!P:P,"Hiệp",'[4]🧪 TC_SA'!Q:Q,"21/03")+COUNTIFS('[5]🧪 TC_SE'!P:P,"Hiệp",'[5]🧪 TC_SE'!Q:Q,"21/03")+COUNTIFS('[6]🧪 TC_RP'!P:P,"Hiệp",'[6]🧪 TC_RP'!Q:Q,"21/03")
A8: 24/03 | B8: =COUNTIF('[1]🧪 TC_PR01'!Q:Q,"24/03")+COUNTIF('[2]🧪 TC_PR02'!Q:Q,"24/03")+COUNTIF('[3]🧪 TC_OT01'!Q:Q,"24/03")+COUNTIF('[4]🧪 TC_SA'!Q:Q,"24/03")+COUNTIF('[5]🧪 TC_SE'!Q:Q,"24/03")+COUNTIF('[6]🧪 TC_RP'!Q:Q,"24/03") | C8: =COUNTIFS('[1]🧪 TC_PR01'!P:P,"Định",'[1]🧪 TC_PR01'!Q:Q,"24/03")+COUNTIFS('[2]🧪 TC_PR02'!P:P,"Định",'[2]🧪 TC_PR02'!Q:Q,"24/03")+COUNTIFS('[3]🧪 TC_OT01'!P:P,"Định",'[3]🧪 TC_OT01'!Q:Q,"24/03")+COUNTIFS('[4]🧪 TC_SA'!P:P,"Định",'[4]🧪 TC_SA'!Q:Q,"24/03")+COUNTIFS('[5]🧪 TC_SE'!P:P,"Định",'[5]🧪 TC_SE'!Q:Q,"24/03")+COUNTIFS('[6]🧪 TC_RP'!P:P,"Định",'[6]🧪 TC_RP'!Q:Q,"24/03") | D8: =COUNTIFS('[1]🧪 TC_PR01'!P:P,"Thanh",'[1]🧪 TC_PR01'!Q:Q,"24/03")+COUNTIFS('[2]🧪 TC_PR02'!P:P,"Thanh",'[2]🧪 TC_PR02'!Q:Q,"24/03")+COUNTIFS('[3]🧪 TC_OT01'!P:P,"Thanh",'[3]🧪 TC_OT01'!Q:Q,"24/03")+COUNTIFS('[4]🧪 TC_SA'!P:P,"Thanh",'[4]🧪 TC_SA'!Q:Q,"24/03")+COUNTIFS('[5]🧪 TC_SE'!P:P,"Thanh",'[5]🧪 TC_SE'!Q:Q,"24/03")+COUNTIFS('[6]🧪 TC_RP'!P:P,"Thanh",'[6]🧪 TC_RP'!Q:Q,"24/03") | E8: =COUNTIFS('[1]🧪 TC_PR01'!P:P,"Vân Anh",'[1]🧪 TC_PR01'!Q:Q,"24/03")+COUNTIFS('[2]🧪 TC_PR02'!P:P,"Vân Anh",'[2]🧪 TC_PR02'!Q:Q,"24/03")+COUNTIFS('[3]🧪 TC_OT01'!P:P,"Vân Anh",'[3]🧪 TC_OT01'!Q:Q,"24/03")+COUNTIFS('[4]🧪 TC_SA'!P:P,"Vân Anh",'[4]🧪 TC_SA'!Q:Q,"24/03")+COUNTIFS('[5]🧪 TC_SE'!P:P,"Vân Anh",'[5]🧪 TC_SE'!Q:Q,"24/03")+COUNTIFS('[6]🧪 TC_RP'!P:P,"Vân Anh",'[6]🧪 TC_RP'!Q:Q,"24/03") | F8: =COUNTIFS('[1]🧪 TC_PR01'!P:P,"Hiệp",'[1]🧪 TC_PR01'!Q:Q,"24/03")+COUNTIFS('[2]🧪 TC_PR02'!P:P,"Hiệp",'[2]🧪 TC_PR02'!Q:Q,"24/03")+COUNTIFS('[3]🧪 TC_OT01'!P:P,"Hiệp",'[3]🧪 TC_OT01'!Q:Q,"24/03")+COUNTIFS('[4]🧪 TC_SA'!P:P,"Hiệp",'[4]🧪 TC_SA'!Q:Q,"24/03")+COUNTIFS('[5]🧪 TC_SE'!P:P,"Hiệp",'[5]🧪 TC_SE'!Q:Q,"24/03")+COUNTIFS('[6]🧪 TC_RP'!P:P,"Hiệp",'[6]🧪 TC_RP'!Q:Q,"24/03")
A9: 25/03 | B9: =COUNTIF('[1]🧪 TC_PR01'!Q:Q,"25/03")+COUNTIF('[2]🧪 TC_PR02'!Q:Q,"25/03")+COUNTIF('[3]🧪 TC_OT01'!Q:Q,"25/03")+COUNTIF('[4]🧪 TC_SA'!Q:Q,"25/03")+COUNTIF('[5]🧪 TC_SE'!Q:Q,"25/03")+COUNTIF('[6]🧪 TC_RP'!Q:Q,"25/03") | C9: =COUNTIFS('[1]🧪 TC_PR01'!P:P,"Định",'[1]🧪 TC_PR01'!Q:Q,"25/03")+COUNTIFS('[2]🧪 TC_PR02'!P:P,"Định",'[2]🧪 TC_PR02'!Q:Q,"25/03")+COUNTIFS('[3]🧪 TC_OT01'!P:P,"Định",'[3]🧪 TC_OT01'!Q:Q,"25/03")+COUNTIFS('[4]🧪 TC_SA'!P:P,"Định",'[4]🧪 TC_SA'!Q:Q,"25/03")+COUNTIFS('[5]🧪 TC_SE'!P:P,"Định",'[5]🧪 TC_SE'!Q:Q,"25/03")+COUNTIFS('[6]🧪 TC_RP'!P:P,"Định",'[6]🧪 TC_RP'!Q:Q,"25/03") | D9: =COUNTIFS('[1]🧪 TC_PR01'!P:P,"Thanh",'[1]🧪 TC_PR01'!Q:Q,"25/03")+COUNTIFS('[2]🧪 TC_PR02'!P:P,"Thanh",'[2]🧪 TC_PR02'!Q:Q,"25/03")+COUNTIFS('[3]🧪 TC_OT01'!P:P,"Thanh",'[3]🧪 TC_OT01'!Q:Q,"25/03")+COUNTIFS('[4]🧪 TC_SA'!P:P,"Thanh",'[4]🧪 TC_SA'!Q:Q,"25/03")+COUNTIFS('[5]🧪 TC_SE'!P:P,"Thanh",'[5]🧪 TC_SE'!Q:Q,"25/03")+COUNTIFS('[6]🧪 TC_RP'!P:P,"Thanh",'[6]🧪 TC_RP'!Q:Q,"25/03") | E9: =COUNTIFS('[1]🧪 TC_PR01'!P:P,"Vân Anh",'[1]🧪 TC_PR01'!Q:Q,"25/03")+COUNTIFS('[2]🧪 TC_PR02'!P:P,"Vân Anh",'[2]🧪 TC_PR02'!Q:Q,"25/03")+COUNTIFS('[3]🧪 TC_OT01'!P:P,"Vân Anh",'[3]🧪 TC_OT01'!Q:Q,"25/03")+COUNTIFS('[4]🧪 TC_SA'!P:P,"Vân Anh",'[4]🧪 TC_SA'!Q:Q,"25/03")+COUNTIFS('[5]🧪 TC_SE'!P:P,"Vân Anh",'[5]🧪 TC_SE'!Q:Q,"25/03")+COUNTIFS('[6]🧪 TC_RP'!P:P,"Vân Anh",'[6]🧪 TC_RP'!Q:Q,"25/03") | F9: =COUNTIFS('[1]🧪 TC_PR01'!P:P,"Hiệp",'[1]🧪 TC_PR01'!Q:Q,"25/03")+COUNTIFS('[2]🧪 TC_PR02'!P:P,"Hiệp",'[2]🧪 TC_PR02'!Q:Q,"25/03")+COUNTIFS('[3]🧪 TC_OT01'!P:P,"Hiệp",'[3]🧪 TC_OT01'!Q:Q,"25/03")+COUNTIFS('[4]🧪 TC_SA'!P:P,"Hiệp",'[4]🧪 TC_SA'!Q:Q,"25/03")+COUNTIFS('[5]🧪 TC_SE'!P:P,"Hiệp",'[5]🧪 TC_SE'!Q:Q,"25/03")+COUNTIFS('[6]🧪 TC_RP'!P:P,"Hiệp",'[6]🧪 TC_RP'!Q:Q,"25/03")
A10: 26/03 | B10: =COUNTIF('[1]🧪 TC_PR01'!Q:Q,"26/03")+COUNTIF('[2]🧪 TC_PR02'!Q:Q,"26/03")+COUNTIF('[3]🧪 TC_OT01'!Q:Q,"26/03")+COUNTIF('[4]🧪 TC_SA'!Q:Q,"26/03")+COUNTIF('[5]🧪 TC_SE'!Q:Q,"26/03")+COUNTIF('[6]🧪 TC_RP'!Q:Q,"26/03") | C10: =COUNTIFS('[1]🧪 TC_PR01'!P:P,"Định",'[1]🧪 TC_PR01'!Q:Q,"26/03")+COUNTIFS('[2]🧪 TC_PR02'!P:P,"Định",'[2]🧪 TC_PR02'!Q:Q,"26/03")+COUNTIFS('[3]🧪 TC_OT01'!P:P,"Định",'[3]🧪 TC_OT01'!Q:Q,"26/03")+COUNTIFS('[4]🧪 TC_SA'!P:P,"Định",'[4]🧪 TC_SA'!Q:Q,"26/03")+COUNTIFS('[5]🧪 TC_SE'!P:P,"Định",'[5]🧪 TC_SE'!Q:Q,"26/03")+COUNTIFS('[6]🧪 TC_RP'!P:P,"Định",'[6]🧪 TC_RP'!Q:Q,"26/03") | D10: =COUNTIFS('[1]🧪 TC_PR01'!P:P,"Thanh",'[1]🧪 TC_PR01'!Q:Q,"26/03")+COUNTIFS('[2]🧪 TC_PR02'!P:P,"Thanh",'[2]🧪 TC_PR02'!Q:Q,"26/03")+COUNTIFS('[3]🧪 TC_OT01'!P:P,"Thanh",'[3]🧪 TC_OT01'!Q:Q,"26/03")+COUNTIFS('[4]🧪 TC_SA'!P:P,"Thanh",'[4]🧪 TC_SA'!Q:Q,"26/03")+COUNTIFS('[5]🧪 TC_SE'!P:P,"Thanh",'[5]🧪 TC_SE'!Q:Q,"26/03")+COUNTIFS('[6]🧪 TC_RP'!P:P,"Thanh",'[6]🧪 TC_RP'!Q:Q,"26/03") | E10: =COUNTIFS('[1]🧪 TC_PR01'!P:P,"Vân Anh",'[1]🧪 TC_PR01'!Q:Q,"26/03")+COUNTIFS('[2]🧪 TC_PR02'!P:P,"Vân Anh",'[2]🧪 TC_PR02'!Q:Q,"26/03")+COUNTIFS('[3]🧪 TC_OT01'!P:P,"Vân Anh",'[3]🧪 TC_OT01'!Q:Q,"26/03")+COUNTIFS('[4]🧪 TC_SA'!P:P,"Vân Anh",'[4]🧪 TC_SA'!Q:Q,"26/03")+COUNTIFS('[5]🧪 TC_SE'!P:P,"Vân Anh",'[5]🧪 TC_SE'!Q:Q,"26/03")+COUNTIFS('[6]🧪 TC_RP'!P:P,"Vân Anh",'[6]🧪 TC_RP'!Q:Q,"26/03") | F10: =COUNTIFS('[1]🧪 TC_PR01'!P:P,"Hiệp",'[1]🧪 TC_PR01'!Q:Q,"26/03")+COUNTIFS('[2]🧪 TC_PR02'!P:P,"Hiệp",'[2]🧪 TC_PR02'!Q:Q,"26/03")+COUNTIFS('[3]🧪 TC_OT01'!P:P,"Hiệp",'[3]🧪 TC_OT01'!Q:Q,"26/03")+COUNTIFS('[4]🧪 TC_SA'!P:P,"Hiệp",'[4]🧪 TC_SA'!Q:Q,"26/03")+COUNTIFS('[5]🧪 TC_SE'!P:P,"Hiệp",'[5]🧪 TC_SE'!Q:Q,"26/03")+COUNTIFS('[6]🧪 TC_RP'!P:P,"Hiệp",'[6]🧪 TC_RP'!Q:Q,"26/03")
A11: 27/03 | B11: =COUNTIF('[1]🧪 TC_PR01'!Q:Q,"27/03")+COUNTIF('[2]🧪 TC_PR02'!Q:Q,"27/03")+COUNTIF('[3]🧪 TC_OT01'!Q:Q,"27/03")+COUNTIF('[4]🧪 TC_SA'!Q:Q,"27/03")+COUNTIF('[5]🧪 TC_SE'!Q:Q,"27/03")+COUNTIF('[6]🧪 TC_RP'!Q:Q,"27/03") | C11: =COUNTIFS('[1]🧪 TC_PR01'!P:P,"Định",'[1]🧪 TC_PR01'!Q:Q,"27/03")+COUNTIFS('[2]🧪 TC_PR02'!P:P,"Định",'[2]🧪 TC_PR02'!Q:Q,"27/03")+COUNTIFS('[3]🧪 TC_OT01'!P:P,"Định",'[3]🧪 TC_OT01'!Q:Q,"27/03")+COUNTIFS('[4]🧪 TC_SA'!P:P,"Định",'[4]🧪 TC_SA'!Q:Q,"27/03")+COUNTIFS('[5]🧪 TC_SE'!P:P,"Định",'[5]🧪 TC_SE'!Q:Q,"27/03")+COUNTIFS('[6]🧪 TC_RP'!P:P,"Định",'[6]🧪 TC_RP'!Q:Q,"27/03") | D11: =COUNTIFS('[1]🧪 TC_PR01'!P:P,"Thanh",'[1]🧪 TC_PR01'!Q:Q,"27/03")+COUNTIFS('[2]🧪 TC_PR02'!P:P,"Thanh",'[2]🧪 TC_PR02'!Q:Q,"27/03")+COUNTIFS('[3]🧪 TC_OT01'!P:P,"Thanh",'[3]🧪 TC_OT01'!Q:Q,"27/03")+COUNTIFS('[4]🧪 TC_SA'!P:P,"Thanh",'[4]🧪 TC_SA'!Q:Q,"27/03")+COUNTIFS('[5]🧪 TC_SE'!P:P,"Thanh",'[5]🧪 TC_SE'!Q:Q,"27/03")+COUNTIFS('[6]🧪 TC_RP'!P:P,"Thanh",'[6]🧪 TC_RP'!Q:Q,"27/03") | E11: =COUNTIFS('[1]🧪 TC_PR01'!P:P,"Vân Anh",'[1]🧪 TC_PR01'!Q:Q,"27/03")+COUNTIFS('[2]🧪 TC_PR02'!P:P,"Vân Anh",'[2]🧪 TC_PR02'!Q:Q,"27/03")+COUNTIFS('[3]🧪 TC_OT01'!P:P,"Vân Anh",'[3]🧪 TC_OT01'!Q:Q,"27/03")+COUNTIFS('[4]🧪 TC_SA'!P:P,"Vân Anh",'[4]🧪 TC_SA'!Q:Q,"27/03")+COUNTIFS('[5]🧪 TC_SE'!P:P,"Vân Anh",'[5]🧪 TC_SE'!Q:Q,"27/03")+COUNTIFS('[6]🧪 TC_RP'!P:P,"Vân Anh",'[6]🧪 TC_RP'!Q:Q,"27/03") | F11: =COUNTIFS('[1]🧪 TC_PR01'!P:P,"Hiệp",'[1]🧪 TC_PR01'!Q:Q,"27/03")+COUNTIFS('[2]🧪 TC_PR02'!P:P,"Hiệp",'[2]🧪 TC_PR02'!Q:Q,"27/03")+COUNTIFS('[3]🧪 TC_OT01'!P:P,"Hiệp",'[3]🧪 TC_OT01'!Q:Q,"27/03")+COUNTIFS('[4]🧪 TC_SA'!P:P,"Hiệp",'[4]🧪 TC_SA'!Q:Q,"27/03")+COUNTIFS('[5]🧪 TC_SE'!P:P,"Hiệp",'[5]🧪 TC_SE'!Q:Q,"27/03")+COUNTIFS('[6]🧪 TC_RP'!P:P,"Hiệp",'[6]🧪 TC_RP'!Q:Q,"27/03")
A12: 28/03 | B12: =COUNTIF('[1]🧪 TC_PR01'!Q:Q,"28/03")+COUNTIF('[2]🧪 TC_PR02'!Q:Q,"28/03")+COUNTIF('[3]🧪 TC_OT01'!Q:Q,"28/03")+COUNTIF('[4]🧪 TC_SA'!Q:Q,"28/03")+COUNTIF('[5]🧪 TC_SE'!Q:Q,"28/03")+COUNTIF('[6]🧪 TC_RP'!Q:Q,"28/03") | C12: =COUNTIFS('[1]🧪 TC_PR01'!P:P,"Định",'[1]🧪 TC_PR01'!Q:Q,"28/03")+COUNTIFS('[2]🧪 TC_PR02'!P:P,"Định",'[2]🧪 TC_PR02'!Q:Q,"28/03")+COUNTIFS('[3]🧪 TC_OT01'!P:P,"Định",'[3]🧪 TC_OT01'!Q:Q,"28/03")+COUNTIFS('[4]🧪 TC_SA'!P:P,"Định",'[4]🧪 TC_SA'!Q:Q,"28/03")+COUNTIFS('[5]🧪 TC_SE'!P:P,"Định",'[5]🧪 TC_SE'!Q:Q,"28/03")+COUNTIFS('[6]🧪 TC_RP'!P:P,"Định",'[6]🧪 TC_RP'!Q:Q,"28/03") | D12: =COUNTIFS('[1]🧪 TC_PR01'!P:P,"Thanh",'[1]🧪 TC_PR01'!Q:Q,"28/03")+COUNTIFS('[2]🧪 TC_PR02'!P:P,"Thanh",'[2]🧪 TC_PR02'!Q:Q,"28/03")+COUNTIFS('[3]🧪 TC_OT01'!P:P,"Thanh",'[3]🧪 TC_OT01'!Q:Q,"28/03")+COUNTIFS('[4]🧪 TC_SA'!P:P,"Thanh",'[4]🧪 TC_SA'!Q:Q,"28/03")+COUNTIFS('[5]🧪 TC_SE'!P:P,"Thanh",'[5]🧪 TC_SE'!Q:Q,"28/03")+COUNTIFS('[6]🧪 TC_RP'!P:P,"Thanh",'[6]🧪 TC_RP'!Q:Q,"28/03") | E12: =COUNTIFS('[1]🧪 TC_PR01'!P:P,"Vân Anh",'[1]🧪 TC_PR01'!Q:Q,"28/03")+COUNTIFS('[2]🧪 TC_PR02'!P:P,"Vân Anh",'[2]🧪 TC_PR02'!Q:Q,"28/03")+COUNTIFS('[3]🧪 TC_OT01'!P:P,"Vân Anh",'[3]🧪 TC_OT01'!Q:Q,"28/03")+COUNTIFS('[4]🧪 TC_SA'!P:P,"Vân Anh",'[4]🧪 TC_SA'!Q:Q,"28/03")+COUNTIFS('[5]🧪 TC_SE'!P:P,"Vân Anh",'[5]🧪 TC_SE'!Q:Q,"28/03")+COUNTIFS('[6]🧪 TC_RP'!P:P,"Vân Anh",'[6]🧪 TC_RP'!Q:Q,"28/03") | F12: =COUNTIFS('[1]🧪 TC_PR01'!P:P,"Hiệp",'[1]🧪 TC_PR01'!Q:Q,"28/03")+COUNTIFS('[2]🧪 TC_PR02'!P:P,"Hiệp",'[2]🧪 TC_PR02'!Q:Q,"28/03")+COUNTIFS('[3]🧪 TC_OT01'!P:P,"Hiệp",'[3]🧪 TC_OT01'!Q:Q,"28/03")+COUNTIFS('[4]🧪 TC_SA'!P:P,"Hiệp",'[4]🧪 TC_SA'!Q:Q,"28/03")+COUNTIFS('[5]🧪 TC_SE'!P:P,"Hiệp",'[5]🧪 TC_SE'!Q:Q,"28/03")+COUNTIFS('[6]🧪 TC_RP'!P:P,"Hiệp",'[6]🧪 TC_RP'!Q:Q,"28/03")
A13: 31/03 | B13: =COUNTIF('[1]🧪 TC_PR01'!Q:Q,"31/03")+COUNTIF('[2]🧪 TC_PR02'!Q:Q,"31/03")+COUNTIF('[3]🧪 TC_OT01'!Q:Q,"31/03")+COUNTIF('[4]🧪 TC_SA'!Q:Q,"31/03")+COUNTIF('[5]🧪 TC_SE'!Q:Q,"31/03")+COUNTIF('[6]🧪 TC_RP'!Q:Q,"31/03") | C13: =COUNTIFS('[1]🧪 TC_PR01'!P:P,"Định",'[1]🧪 TC_PR01'!Q:Q,"31/03")+COUNTIFS('[2]🧪 TC_PR02'!P:P,"Định",'[2]🧪 TC_PR02'!Q:Q,"31/03")+COUNTIFS('[3]🧪 TC_OT01'!P:P,"Định",'[3]🧪 TC_OT01'!Q:Q,"31/03")+COUNTIFS('[4]🧪 TC_SA'!P:P,"Định",'[4]🧪 TC_SA'!Q:Q,"31/03")+COUNTIFS('[5]🧪 TC_SE'!P:P,"Định",'[5]🧪 TC_SE'!Q:Q,"31/03")+COUNTIFS('[6]🧪 TC_RP'!P:P,"Định",'[6]🧪 TC_RP'!Q:Q,"31/03") | D13: =COUNTIFS('[1]🧪 TC_PR01'!P:P,"Thanh",'[1]🧪 TC_PR01'!Q:Q,"31/03")+COUNTIFS('[2]🧪 TC_PR02'!P:P,"Thanh",'[2]🧪 TC_PR02'!Q:Q,"31/03")+COUNTIFS('[3]🧪 TC_OT01'!P:P,"Thanh",'[3]🧪 TC_OT01'!Q:Q,"31/03")+COUNTIFS('[4]🧪 TC_SA'!P:P,"Thanh",'[4]🧪 TC_SA'!Q:Q,"31/03")+COUNTIFS('[5]🧪 TC_SE'!P:P,"Thanh",'[5]🧪 TC_SE'!Q:Q,"31/03")+COUNTIFS('[6]🧪 TC_RP'!P:P,"Thanh",'[6]🧪 TC_RP'!Q:Q,"31/03") | E13: =COUNTIFS('[1]🧪 TC_PR01'!P:P,"Vân Anh",'[1]🧪 TC_PR01'!Q:Q,"31/03")+COUNTIFS('[2]🧪 TC_PR02'!P:P,"Vân Anh",'[2]🧪 TC_PR02'!Q:Q,"31/03")+COUNTIFS('[3]🧪 TC_OT01'!P:P,"Vân Anh",'[3]🧪 TC_OT01'!Q:Q,"31/03")+COUNTIFS('[4]🧪 TC_SA'!P:P,"Vân Anh",'[4]🧪 TC_SA'!Q:Q,"31/03")+COUNTIFS('[5]🧪 TC_SE'!P:P,"Vân Anh",'[5]🧪 TC_SE'!Q:Q,"31/03")+COUNTIFS('[6]🧪 TC_RP'!P:P,"Vân Anh",'[6]🧪 TC_RP'!Q:Q,"31/03") | F13: =COUNTIFS('[1]🧪 TC_PR01'!P:P,"Hiệp",'[1]🧪 TC_PR01'!Q:Q,"31/03")+COUNTIFS('[2]🧪 TC_PR02'!P:P,"Hiệp",'[2]🧪 TC_PR02'!Q:Q,"31/03")+COUNTIFS('[3]🧪 TC_OT01'!P:P,"Hiệp",'[3]🧪 TC_OT01'!Q:Q,"31/03")+COUNTIFS('[4]🧪 TC_SA'!P:P,"Hiệp",'[4]🧪 TC_SA'!Q:Q,"31/03")+COUNTIFS('[5]🧪 TC_SE'!P:P,"Hiệp",'[5]🧪 TC_SE'!Q:Q,"31/03")+COUNTIFS('[6]🧪 TC_RP'!P:P,"Hiệp",'[6]🧪 TC_RP'!Q:Q,"31/03")
A14: TỔNG CỘNG | B14: =SUM(B4:B13) | C14: =SUM(C4:C13) | D14: =SUM(D4:D13) | E14: =SUM(E4:E13) | F14: =SUM(F4:F13)

Sheet 🐞 Bug Tracker
A1: BUG TRACKER — PROFIX PHASE 1
A2: Bug ID | B2: TC ID Liên quan | C2: Title | D2: Module | E2: Severity | F2: Priority | G2: Environment | H2: Steps to Reproduce | I2: Expected | J2: Actual | K2: Assigned To (Dev) | L2: Status
A3: BUG-001 | B3: PR02-HAPPY-001 | C3: [Công thức tính phí] Nhấn Xác nhận sau khi thêm cấu phần Số cố định không có phản hồi | D3: PR02 | E3: S2 | F3: P1 | G3: Staging/Chrome | H3: 1. Thêm mới CT 2. Thêm cấu phần Số cố định 3. Nhấn Xác nhận | I3: Lưu thành công, có Toast message | J3: Màn hình đứng im, không có phản hồi | K3: [Dev BE] | L3: Open

Sheet II.5.1.1.2
A1: TEST CASES — II.5.1.1.2. Thêm mới Nghiệp vụ (SPDV cấp 1)
A2: TC_ID | B2: Module | C2: Feature | D2: Title | E2: Type | F2: Category | G2: Priority | H2: Precondition | I2: Steps | J2: Expected | K2: URD_Ref | L2: BR_Ref | M2: Trace_ID | N2: Note | O2: Status R1 | P2: Tester R1 | Q2: Date R1 | R2: Status R2 | S2: Tester R2 | T2: Date R2 | U2: Final Status
A3: PR01-BR01-NEG-001 | B3: PR01 | C3: Nghiệp vụ (SPDV cấp 1) - Thêm mới | D3: Thiếu trường bắt buộc khi thêm Nghiệp vụ → chặn lưu | E3: Negative | F3: Smoke | G3: P1 | H3: 1. Maker đăng nhập (ngày T) tồn tại kết nối hệ thống. | I3: 1) Mở PR01 → nhấn “Thêm mới Nghiệp vụ”; 2) Bỏ trống 1+ trường bắt buộc (*); 3) Nhấn “Xác nhận”; 4) Quan sát thông báo | J3: (i) Logic: Thiếu mandatory → từ chối lưu. (ii) UI: Highlight trường lỗi/toast lỗi; nút vẫn ở form. (iii) OT.01: không áp dụng. (iv) Data: Không phát sinh bản ghi/audit. | K3: II.5.1.1.2/BR_01 | L3: BR_01 | M3: BR01-NGHV-REQ | U3: =IF(R3<>"", R3, O3)
A4: PR01-BR02-NEG-002 | B4: PR01 | C4: Nghiệp vụ (SPDV cấp 1) - Thêm mới | D4: Đóng/Hủy form Thêm mới Nghiệp vụ → không lưu dữ liệu | E4: Negative | F4: Regression | G4: P2 | H4: 1. Form Thêm mới Nghiệp vụ đang mở đã nhập vài trường. | I4: 1) Nhập vài trường; 2) Nhấn “Đóng/Hủy”; 3) Xác nhận (nếu có); 4) Về lưới tìm theo dữ liệu vừa nhập | J4: (i) Logic: Đóng/Hủy → không lưu. (ii) UI: Form đóng, không có toast thành công. (iii) OT.01: không áp dụng. (iv) Data: Không có bản ghi/audit. | K4: II.5.1.1.2/BR_02 | L4: BR_02 | M4: BR02-NGHV-CLOSE | U4: =IF(R4<>"", R4, O4)
A5: PR01-BR03-HAPPY-003 | B5: PR01 | C5: Nghiệp vụ (SPDV cấp 1) - Auto code | D5: Mã Nghiệp vụ tự sinh 2 ký tự tăng dần & duy nhất (01→02) | E5: Happy | F5: Smoke | G5: P1 | H5: 1. Maker đăng nhập hệ thống rỗng hoặc đang có mã 01. | I5: 1) Tạo Nghiệp vụ A hợp lệ → “Xác nhận”; 2) Tạo Nghiệp vụ B hợp lệ → “Xác nhận”; 3) Mở chi tiết A,B xem trường Mã | J5: (i) Logic: Mã auto 2 chữ số tăng dần, không trùng. (ii) UI: Field Mã hiển thị đúng và read-only. (iii) OT.01: Cả 2 bản ghi ở “Chờ duyệt”. (iv) Data: Audit CREATE ghi nhận mã. | K5: II.5.1.1.2/BR_03; II.5.1.1.2/BR_04 | L5: BR_03;BR_04 | M5: BR03-NGHV-AUTO | U5: =IF(R5<>"", R5, O5)
A6: PR01-BR03-BOUND-004 | B6: PR01 | C6: Nghiệp vụ (SPDV cấp 1) - Auto code | D6: Vượt ngưỡng mã tự tăng (tạo bản ghi thứ 100) → chặn | E6: Boundary | F6: Regression | G6: P2 | H6: 1. Đã tồn tại 99 Nghiệp vụ (01 trong môi trường test Maker đăng nhập. | I6: 1) “Thêm mới Nghiệp vụ” hợp lệ; 2) “Xác nhận” | J6: (i) Logic: Không sinh mã >99 → chặn. (ii) UI: Thông báo/tooltip nêu lý do. (iii) OT.01: không áp dụng. (iv) Data: Không tạo bản ghi. | K6: II.5.1.1.2/BR_03 | L6: BR_03 | M6: BR03-NGHV-LIMIT | U6: =IF(R6<>"", R6, O6)
A7: PR01-BR04-HAPPY-005 | B7: PR01 | C7: Nghiệp vụ (SPDV cấp 1) - Field control | D7: Không cho phép chỉnh sửa trường Mã Nghiệp vụ | E7: Happy | F7: Regression | G7: P3 | H7: 1. Có bản ghi Nghiệp vụ 'Chờ duyệt' hoặc 'Đã duyệt'. | I7: 1) Mở chi tiết bản ghi; 2) Nhấn “Sửa”; 3) Thử sửa trường Mã | J7: (i) Logic: Trường Mã không sửa được. (ii) UI: Ô Mã disabled/read-only. (iii) OT.01: Không sinh tác vụ nếu chỉ cố sửa Mã. (iv) Data: Mã giữ nguyên. | K7: II.5.1.1.2/BR_04 | L7: BR_04 | M7: BR04-NGHV-CODE-RO | U7: =IF(R7<>"", R7, O7)
A8: PR01-BR05-HAPPY-006 | B8: PR01 | C8: Nghiệp vụ (SPDV cấp 1) - Hiển thị | D8: Chưa duyệt không hiển thị trên lưới Danh mục SPDV | E8: Happy | F8: Smoke | G8: P1 | H8: 1. Vừa tạo 1 Nghiệp vụ (Chờ duyệt). | I8: 1) Về lưới PR01; 2) Lọc theo Tên/Mã vừa tạo | J8: (i) Logic: Bản ghi chưa duyệt → không hiển thị. (ii) UI: Không có kết quả. (iii) OT.01: Có tác vụ ở “Tác vụ chờ duyệt”. (iv) Data: Trạng thái=Chờ duyệt lưu DB. | K8: II.5.1.1.2/BR_05; II.5.1.1.2/BR_06 | L8: BR_05;BR_06 | M8: BR05-NGHV-NOTSHOW | U8: =IF(R8<>"", R8, O8)
A9: PR01-BR06-HAPPY-007 | B9: PR01 | C9: Nghiệp vụ (SPDV cấp 1) - Tác vụ | D9: Khoản thêm mới sinh tác vụ “Chờ duyệt” | E9: Happy | F9: Smoke | G9: P1 | H9: 1. Vừa lưu Nghiệp vụ mới. | I9: 1) Mở “Tác vụ chờ duyệt”; 2) Tìm theo Mã/Tên | J9: (i) Logic: Phải có tác vụ chờ duyệt. (ii) UI: Dòng tác vụ xuất hiện. (iii) OT.01: Log tạo tác vụ. (iv) Data: Audit CREATE/TASK. | K9: II.5.1.1.2/BR_06 | L9: BR_06 | M9: BR06-NGHV-TASK | U9: =IF(R9<>"", R9, O9)
A10: PR01-BR07-HAPPY-008 | B10: PR01 | C10: Nghiệp vụ (SPDV cấp 1) - Cấp khai báo | D10: “Cấp khai báo” auto =1 và không cho sửa | E10: Happy | F10: Regression | G10: P3 | H10: 1. Form Thêm mới Nghiệp vụ đang mở. | I10: 1) Quan sát trường “Cấp khai báo”; 2) Thử thay đổi; 3) Lưu bản ghi hợp lệ | J10: (i) Logic: Giá trị mặc định=1 & không sửa được. (ii) UI: Ô hiển thị 1 và disabled. (iii) OT.01: Bản ghi Chờ duyệt. (iv) Data: Lưu cấp= 1. | K10: II.5.1.1.2/BR_07 | L10: BR_07 | M10: BR07-NGHV-LEVEL1 | U10: =IF(R10<>"", R10, O10)
A11: PR01-BR08-NEG-009 | B11: PR01 | C11: Nghiệp vụ (SPDV cấp 1) - Hiệu lực | D11: Ngày hiệu lực/ngày hết hiệu lực quá khứ → chặn | E11: Negative | F11: Smoke | G11: P1 | H11: 1. Form Thêm mới Nghiệp vụ. | I11: 1) Chọn Ngày hiệu lực < T → “Xác nhận”; 2) Chọn Ngày hết hiệu lực < T → “Xác nhận” | J11: (i) Logic: Không cho ngày quá khứ. (ii) UI: Báo lỗi tại trường ngày. (iii) OT.01: không áp dụng. (iv) Data: Không lưu. | K11: II.5.1.1.2/BR_08 | L11: BR_08 | M11: BR08-NGHV-DATEPAST | U11: =IF(R11<>"", R11, O11)
A12: PR01-BR09-HAPPY-010 | B12: PR01 | C12: Nghiệp vụ (SPDV cấp 1) - Trạng thái theo ngày | D12: Trạng thái hoạt động theo Ngày hiệu lực (T=Đang hoạt động; >T=Không hoạt động) | E12: Happy | F12: Regression | G12: P2 | H12: 1. Tạo 2 bản ghi NV: A hiệu lực=T B hiệu lực>T. | I12: 1) Duyệt A và B; 2) Mở chi tiết kiểm tra; 3) Quan sát trạng thái hoạt động | J12: (i) Logic: A=Đang hoạt động; B=Không hoạt động (hoặc Chưa). (ii) UI: Trạng thái hiển thị đúng. (iii) OT.01: APPROVE 2 bản ghi. (iv) Data: Audit APPROVE; trạng thái lưu đúng. | K12: II.5.1.1.2/BR_09 | L12: BR_09 | M12: BR09-NGHV-STATUS | U12: =IF(R12<>"", R12, O12)
A13: PR01-BR10-HAPPY-011 | B13: PR01 | C13: Nghiệp vụ (SPDV cấp 1) - Đổi trạng thái | D13: Đổi trạng thái qua cập nhật “Ngày hết hiệu lực” | E13: Happy | F13: Regression | G13: P2 | H13: 1. Có NV đang Đang hoạt động Maker có quyền sửa. | I13: 1) Mở chi tiết → “Sửa”; 2) Cập nhật Ngày hết hiệu lực=T; 3) “Xác nhận” (sinh tác vụ); 4) Checker duyệt; 5) Kiểm tra trạng thái | J13: (i) Logic: Versioning C: cập nhật in-place; hết hiệu lực → Ngưng hoạt động; ngược lại cập nhật lại ngày để hoạt động. (ii) UI: Trạng thái đổi sau duyệt. (iii) OT.01: UPDATE + APPROVE. (iv) Data: Không tạo version record mới. | K13: II.5.1.1.2/BR_10 | L13: BR_10 | M13: BR10-NGHV-STATE-CHANGE | N13: Tuân thủ bối cảnh dự án | U13: =IF(R13<>"", R13, O13)
A14: PR01-BR11-HAPPY-012 | B14: PR01 | C14: Nghiệp vụ (SPDV cấp 1) - Metadata | D14: “Ngày tạo” tự sinh đúng định dạng | E14: Happy | F14: Regression | G14: P3 | H14: 1. Có NV vừa tạo. | I14: 1) Mở chi tiết NV; 2) Quan sát 'Ngày tạo' | J14: (i) Logic: Do hệ thống sinh theo định dạng chuẩn. (ii) UI: YYYY-MM-DD HH:MM:SS. (iii) OT.01: không áp dụng. (iv) Data: Audit time khớp. | K14: II.5.1.1.2/BR_11 | L14: BR_11 | M14: BR11-NGHV-CREATEDAT | U14: =IF(R14<>"", R14, O14)
A15: PR01-BR12-HAPPY-013 | B15: PR01 | C15: Nghiệp vụ (SPDV cấp 1) - Metadata | D15: “Người tạo” = username Maker | E15: Happy | F15: Regression | G15: P3 | H15: 1. Có NV do Maker tạo. | I15: 1) Mở chi tiết NV; 2) Quan sát 'Người tạo' | J15: (i) Logic: Lưu đúng username. (ii) UI: Hiển thị chính xác. (iii) OT.01: không áp dụng. (iv) Data: Audit CREATE ghi user. | K15: II.5.1.1.2/BR_12 | L15: BR_12 | M15: BR12-NGHV-CREATEDBY | U15: =IF(R15<>"", R15, O15)
A16: PR01-BR01D-NEG-014 | B16: PR01 | C16: SPDV chi tiết - Thêm mới | D16: Thiếu trường bắt buộc khi thêm SPDV chi tiết → chặn | E16: Negative | F16: Smoke | G16: P1 | H16: 1. Có NV cấp 1 đã duyệt Maker đăng nhập. | I16: 1) Tại NV cha → nhấn “+”; 2) Bỏ trống 1+ trường bắt buộc; 3) “Xác nhận” | J16: (i) Logic: Thiếu mandatory → chặn. (ii) UI: Highlight lỗi. (iii) OT.01: không áp dụng. (iv) Data: Không tạo. | K16: II.5.1.1.3/BR_01 | L16: BR_01 | M16: BR01D-SPDV-REQ
A17: PR01-BR02D-NEG-015 | B17: PR01 | C17: SPDV chi tiết - Thêm mới | D17: Đóng/Hủy form Thêm SPDV chi tiết → không lưu dữ liệu | E17: Negative | F17: Regression | G17: P2 | H17: 1. Form Thêm SPDV chi tiết đang mở. | I17: 1) Nhập vài trường; 2) Nhấn 'Đóng/Hủy'; 3) Trở về lưới kiểm tra | J17: (i) Logic: Hủy → không lưu. (ii) UI: Form đóng; không có toast thành công. (iii) OT.01: không áp dụng. (iv) Data: Không phát sinh bản ghi. | K17: II.5.1.1.3/BR_02 | L17: BR_02 | M17: BR02D-SPDV-CLOSE
A18: PR01-BR03D-HAPPY-016 | B18: PR01 | C18: SPDV chi tiết - Hiển thị danh sách | D18: Chỉ hiển thị bản ghi đã được Checker phê duyệt | E18: Happy | F18: Smoke | G18: P1 | H18: 1. Có 1 SPDV chi tiết vừa tạo (Chờ duyệt). | I18: 1) Về lưới Danh mục SPDV; 2) Lọc theo tên SPDV chi tiết vừa tạo; 3) Duyệt; 4) Refresh lưới | J18: (i) Logic: Chưa duyệt → không hiển thị; sau duyệt → hiển thị. (ii) UI: Lưới phản ánh đúng. (iii) OT.01: Có tác vụ/APPROVE. (iv) Data: Ghi trạng thái theo thực tế. | K18: II.5.1.1.3/BR_03 | L18: BR_03 | M18: BR03D-SPDV-VISIBILITY
A19: PR01-BR04D-HAPPY-017 | B19: PR01 | C19: SPDV chi tiết - Auto code | D19: Mã SPDV chi tiết = Mã cha + 2 số tự tăng; duy nhất | E19: Happy | F19: Smoke | G19: P1 | H19: 1. NV cha mã 06 đã duyệt Maker đăng nhập. | I19: 1) Tại 06 → nhấn “+”; 2) Nhập hợp lệ → “Xác nhận”; 3) Tạo thêm 1 bản chi tiết; 4) Kiểm tra trường Mã | J19: (i) Logic: Mã = 06xx tăng dần; không trùng. (ii) UI: Field Mã read-only. (iii) OT.01: Các bản ghi ở Chờ duyệt. (iv) Data: Audit CREATE chứa mã auto. | K19: II.5.1.1.3/BR_04; II.5.1.1.3/BR_05 | L19: BR_04;BR_05 | M19: BR04D-SPDV-AUTO
A20: PR01-BR06D-HAPPY-018 | B20: PR01 | C20: SPDV chi tiết - Ngữ cảnh cha | D20: “Cấp SPDV liền trước” hiển thị “Mã - Tên” cấp cha khi bấm “+” | E20: Happy | F20: Regression | G20: P3 | H20: 1. Có NV cha đã duyệt Maker đăng nhập. | I20: 1) Tại bản ghi cha → bấm “+”; 2) Quan sát trường “Cấp SPDV liền trước” | J20: (i) Logic: Hiển thị đúng Mã-Tên cha. (ii) UI: Label/field hiển thị giá trị cha. (iii) OT.01: không áp dụng. (iv) Data: Không đổi. | K20: II.5.1.1.3/BR_06 | L20: BR_06 | M20: BR06D-SPDV-PARENTCTX
A21: PR01-BR07D-BOUND-019 | B21: PR01 | C21: SPDV chi tiết - Giới hạn cấp | D21: Sản phẩm không vượt số cấp tối đa PRODUCT_LEVEL | E21: Boundary | F21: Regression | G21: P2 | H21: 1. PRODUCT_LEVEL=n (ví dụ cây đang ở cấp n. | I21: 1) Thử tạo thêm cấp con tại bản ghi cấp n; 2) Quan sát thông báo; 3) “Xác nhận” | J21: (i) Logic: Không cho vượt cấp tối đa. (ii) UI: Disable/ cảnh báo phù hợp. (iii) OT.01: không áp dụng. (iv) Data: Không tạo. | K21: II.5.1.1.3/BR_07; II.5.1.1.3/BR_10 | L21: BR_07;BR_10 | M21: BR07D-SPDV-MAXLVL
A22: PR01-BR08D-NEG-020 | B22: PR01 | C22: SPDV chi tiết - Quan hệ cha | D22: Bắt buộc có đủ n−1 cấp cha trước khi khai báo cấp cuối | E22: Negative | F22: Smoke | G22: P1 | H22: 1. PRODUCT_LEVEL=n thiếu 1 cấp cha ở giữa. | I22: 1) Cố tạo SPDV cấp n; 2) “Xác nhận” | J22: (i) Logic: Thiếu cấp cha → chặn. (ii) UI: Thông báo nêu rõ cấp thiếu. (iii) OT.01: không áp dụng. (iv) Data: Không tạo. | K22: II.5.1.1.3/BR_08 | L22: BR_08 | M22: BR08D-SPDV-MISS-PARENT
A23: PR01-BR09D-HAPPY-021 | B23: PR01 | C23: SPDV chi tiết - Cảnh báo cấp cuối | D23: Hiển thị thông tin “Đây là cấp cuối cùng…” khi khai báo cấp n | E23: Happy | F23: Regression | G23: P3 | H23: 1. Đang tạo SPDV ở cấp n. | I23: 1) Mở form tạo ở cấp n; 2) Quan sát thông tin/label cảnh báo cấp cuối | J23: (i) Logic: Hệ thống hiển thị thông tin cấp cuối. (ii) UI: Text cảnh báo hiển thị đúng. (iii) OT.01: không áp dụng. (iv) Data: không đổi. | K23: II.5.1.1.3/BR_09 | L23: BR_09 | M23: BR09D-SPDV-LASTLEVEL
A24: PR01-BR11D-NEG-022 | B24: PR01 | C24: SPDV chi tiết - Hiệu lực | D24: Ngày hiệu lực/hết hiệu lực quá khứ → chặn | E24: Negative | F24: Smoke | G24: P1 | H24: 1. Form Thêm SPDV chi tiết. | I24: 1) Chọn ngày hiệu lực < T → “Xác nhận”; 2) Chọn ngày hết hiệu lực < T → “Xác nhận” | J24: (i) Logic: Không cho ngày quá khứ. (ii) UI: Báo lỗi tại trường ngày. (iii) OT.01: không áp dụng. (iv) Data: Không lưu. | K24: II.5.1.1.3/BR_11 | L24: BR_11 | M24: BR11D-SPDV-DATEPAST
A25: PR01-BR12D-HAPPY-023 | B25: PR01 | C25: SPDV chi tiết - Trạng thái theo ngày | D25: Trạng thái hoạt động theo Ngày hiệu lực (T=Đang; >T=Chưa) | E25: Happy | F25: Regression | G25: P2 | H25: 1. Tạo 2 SPDV chi tiết: A hiệu lực=T B hiệu lực>T. | I25: 1) Duyệt A,B; 2) Mở chi tiết; 3) Kiểm tra trạng thái | J25: (i) Logic: A=Đang hoạt động; B=Chưa hoạt động. (ii) UI: Trạng thái hiển thị đúng. (iii) OT.01: APPROVE. (iv) Data: Audit đúng. | K25: II.5.1.1.3/BR_12 | L25: BR_12 | M25: BR12D-SPDV-STATUS
A26: PR01-BR13D-NEG-024 | B26: PR01 | C26: SPDV chi tiết - Quan hệ hiệu lực | D26: Hiệu lực con phải nằm trong khoảng hiệu lực cha → vi phạm bị chặn | E26: Negative | F26: Smoke | G26: P1 | H26: 1. Cha hiệu lực [T1–T2] Maker đăng nhập. | I26: 1) Tạo SPDV con với [T1' < T1] hoặc [T2' > T2]; 2) “Xác nhận” | J26: (i) Logic: Con vượt ngoài cha → chặn. (ii) UI: Lỗi nêu rõ quan hệ cha-con. (iii) OT.01: không áp dụng. (iv) Data: Không tạo. | K26: II.5.1.1.3/BR_13 | L26: BR_13 | M26: BR13D-SPDV-CHILD-INHERIT
A27: PR01-BR14D-HAPPY-025 | B27: PR01 | C27: SPDV chi tiết - Đổi trạng thái | D27: Đổi trạng thái qua cập nhật “Ngày hết hiệu lực” | E27: Happy | F27: Regression | G27: P2 | H27: 1. Có SPDV chi tiết đang Đang hoạt động Maker có quyền sửa. | I27: 1) Mở chi tiết → “Sửa”; 2) Đặt Ngày hết hiệu lực=T; 3) “Xác nhận” (sinh tác vụ); 4) Checker duyệt; 5) Kiểm tra trạng thái | J27: (i) Logic: Hết hiệu lực → Ngưng hoạt động; có thể đổi ngược bằng hiệu lực mới. (ii) UI: Trạng thái đổi sau duyệt. (iii) OT.01: UPDATE + APPROVE (Versioning C). (iv) Data: Cập nhật in-place. | K27: II.5.1.1.3/BR_14 | L27: BR_14 | M27: BR14D-SPDV-STATE-CHANGE
... A29: PR01-BR18D-HAPPY-027 | B29: PR01 | C29: SPDV chi tiết - Metadata | D29: “Người tạo” = username Maker | E29: Happy | F29: Regression | G29: P3 | H29: 1. Có SPDV chi tiết do Maker tạo. | I29: 1) Mở chi tiết; 2) Kiểm tra 'Người tạo' | J29: (i) Logic: Lưu đúng username Maker. (ii) UI: Hiển thị chính xác. (iii) OT.01: không áp dụng. (iv) Data: Audit CREATE ghi user. | K29: II.5.1.1.3/BR_18 | L29: BR_18 | M29: BR18D-SPDV-CREATEDBY
A30: PR01-FLOW-OT01-HAPPY-028 | B30: PR01 | C30: OT.01 - Phê duyệt (NV & SPDV) | D30: Checker phê duyệt → bản ghi hiển thị trên lưới và khả dụng | E30: Happy | F30: Smoke | G30: P1 | H30: 1. Có ít nhất 1 NV và 1 SPDV chi tiết ở trạng thái 'Chờ duyệt'. | I30: 1) Checker mở “Tác vụ chờ duyệt”; 2) Chọn tác vụ NV → “Duyệt”; 3) Chọn tác vụ SPDV → “Duyệt”; 4) Về lưới kiểm tra hiển thị | J30: (i) Logic: Trạng thái chuyển “Đã duyệt”, bản ghi khả dụng. (ii) UI: Xuất hiện trên lưới. (iii) OT.01: Audit APPROVE (user,timestamp). (iv) Data: Lưu trạng thái & log. | K30: II.5.1.1.2/BR_06; II.5.1.1.3/BR_16 | L30: BR_06;BR_16 | M30: FLOW-APPROVE | U30: =IF(R16<>"", R16, O16)
A31: PR01-FLOW-OT01-NEG-029 | B31: PR01 | C31: OT.01 - Từ chối (NV & SPDV) | D31: Checker từ chối → không hiển thị trên lưới | E31: Negative | F31: Smoke | G31: P1 | H31: 1. Có 1 NV/SPDV chi tiết ở Chờ duyệt. | I31: 1) Checker vào “Tác vụ chờ duyệt”; 2) Chọn tác vụ → “Từ chối”, nhập lý do; 3) Về lưới kiểm tra | J31: (i) Logic: Bị từ chối → không hiển thị/không áp dụng. (ii) UI: Lý do hiển thị tại lịch sử. (iii) OT.01: Audit REJECT. (iv) Data: Trạng thái Từ chối lưu DB. | K31: II.5.1.1.2/BR_05; II.5.1.1.3/BR_15 | L31: BR_05;BR_15 | M31: FLOW-REJECT | U31: =IF(R17<>"", R17, O17)
A32: PR01-FLOW-EFF-HAPPY-030 | B32: PR01 | C32: OT.01 - Sửa hiệu lực (Versioning C) | D32: Sửa ngày hiệu lực hợp lệ ở mọi trạng thái → cập nhật in-place sau duyệt | E32: Happy | F32: Regression | G32: P2 | H32: 1. Có NV hoặc SPDV chi tiết 'Đã duyệt' Maker có quyền sửa. | I32: 1) Maker mở chi tiết → “Sửa”; 2) Nhập [T1'–T2'] hợp lệ (không quá khứ/không vượt cha/không end<start); 3) “Xác nhận” (sinh tác vụ); 4) Checker duyệt; 5) Kiểm tra lại chi tiết | J32: (i) Logic: Versioning C: update in-place; không tạo version mới. (ii) UI: Tác vụ xuất hiện và sau duyệt hiệu lực mới hiển thị. (iii) OT.01: Audit UPDATE + APPROVE. (iv) Data: Bản ghi hiện hữu được cập nhật. | K32: II.5.1.1.2; II.5.1.1.3 | L32: (theo bối cảnh dự án) | M32: FLOW-EFF-VALID | N32: Áp dụng rule hiệu lực chung của dự án | U32: =IF(R18<>"", R18, O18)
A33: PR01-FLOW-EFF-NEG-031 | B33: PR01 | C33: OT.01 - Sửa hiệu lực (Versioning C) | D33: Sửa hiệu lực end<start/ra quá khứ/child vượt cha → chặn & không tạo tác vụ | E33: Negative | F33: Regression | G33: P2 | H33: 1. Có bản ghi ở trạng thái bất kỳ Maker mở Sửa. | I33: 1) Nhập Ngày hết < Ngày hiệu lực; 2) Hoặc chọn ngày quá khứ; 3) Với SPDV con: đặt hiệu lực vượt cha; 4) “Xác nhận” | J33: (i) Logic: Vi phạm logic hiệu lực → chặn. (ii) UI: Báo lỗi chi tiết. (iii) OT.01: Không sinh tác vụ. (iv) Data: Không thay đổi. | K33: II.5.1.1.2/BR_08; II.5.1.1.3/BR_11; II.5.1.1.3/BR_13 | M33: FLOW-EFF-INVALID | U33: =IF(R19<>"", R19, O19)
A34: PR01-UI-01-OPEN-032 | B34: PR01 | C34: UI - Thêm mới Nghiệp vụ | D34: Mở form Thêm mới Nghiệp vụ hiển thị đúng & “Cấp khai báo”=1 (read-only) | E34: Happy | F34: Regression | G34: P3 | H34: 1. Maker đăng nhập. | I34: 1) PR01 → “Thêm mới Nghiệp vụ”; 2) Quan sát các trường; 3) Kiểm tra “Cấp khai báo”=1 và disabled | J34: (i) Logic: không áp dụng. (ii) UI: Form/fields hiển thị đúng trạng thái. (iii) OT.01: không áp dụng. (iv) Data: không đổi. | K34: II.5.1.1.2/Step-2 | L34: UI-FUNC.01 | M34: UI-NGHV-OPEN | N34: UI-only; logic đã cover ở BR_07 | U34: =IF(R20<>"", R20, O20)
A35: PR01-UI-02-OPEN-033 | B35: PR01 | C35: UI - Thêm mới SPDV chi tiết | D35: Mở form Thêm SPDV chi tiết từ cấp cha hiển thị “Cấp SPDV liền trước: Mã - Tên” | E35: Happy | F35: Regression | G35: P3 | H35: 1. Có SPDV cha đã duyệt Maker đăng nhập. | I35: 1) Tại bản ghi cha → bấm “+”; 2) Quan sát label/field “Cấp SPDV liền trước” | J35: (i) Logic: không áp dụng. (ii) UI: Hiển thị đúng Mã - Tên cha. (iii) OT.01: không áp dụng. (iv) Data: không đổi. | K35: II.5.1.1.3/BR_06 | L35: UI-FUNC.02 | M35: UI-SPDV-OPEN | U35: =IF(R21<>"", R21, O21)
A36: PR01-UI-03-VIEW-034 | B36: PR01 | C36: UI - Xem | D36: Xem chi tiết NV/SPDV ở chế độ read-only | E36: Happy | F36: Regression | G36: P3 | H36: 1. Có dữ liệu NV/SPDV. | I36: 1) Chọn 1 bản ghi → “Xem”; 2) Kiểm tra trạng thái field (read-only) | J36: (i) Logic: không áp dụng. (ii) UI: Màn hình chỉ xem (khóa chỉnh sửa). (iii) OT.01: không áp dụng. (iv) Data: không đổi. | K36: II.5.1.1.1 | L36: UI-FUNC.03 | M36: UI-VIEW-RO | U36: =IF(R22<>"", R22, O22)
A37: PR01-UI-04-EDITNAV-035 | B37: PR01 | C37: UI - Sửa | D37: Điều hướng Sửa → Lưu → quay lại lưới vẫn giữ giá trị đã lưu | E37: Happy | F37: Regression | G37: P3 | H37: 1. Có bản ghi NV hoặc SPDV Maker có quyền sửa. | I37: 1) Chọn bản ghi → “Sửa”; 2) Đổi mô tả → “Xác nhận”; 3) Về lưới → mở lại chi tiết | J37: (i) Logic: không áp dụng. (ii) UI: Giá trị đã lưu hiển thị đúng; điều hướng mượt. (iii) OT.01: Nếu thuộc luồng duyệt → sinh tác vụ. (iv) Data: Audit UPDATE ghi trường thay đổi. | K37: II.5.1.1.1 | L37: UI-FUNC.04 | M37: UI-EDIT-NAV | N37: Không kiểm rule hiệu lực (đã có FLOW-EFF-…) | U37: =IF(R23<>"", R23, O23)
A38: PR01-UI-05-FILTER-036 | B38: PR01 | C38: UI - Lọc | D38: Tìm kiếm theo Tên/Mã/Trạng thái; “Xóa lọc” khôi phục lưới | E38: Happy | F38: Regression | G38: P2 | H38: 1. Có nhiều bản ghi NV & SPDV. | I38: 1) Lọc theo Tên; 2) Lọc theo Mã; 3) Lọc theo Trạng thái; 4) Nhấn “Xóa lọc” | J38: (i) Logic: không áp dụng. (ii) UI: Bộ lọc trả kết quả đúng; Xóa lọc khôi phục. (iii) OT.01: không áp dụng. (iv) Data: không đổi. | K38: II.5.1.1.1 | L38: UI-FUNC.05 | M38: UI-FILTER-BASIC | U38: =IF(R24<>"", R24, O24)
A39: PR01-UI-06-EXPORT-037 | B39: PR01 | C39: UI - Tải xuống | D39: Export dữ liệu lưới ra .xlsx (theo lọc & toàn bộ) | E39: Happy | F39: Regression | G39: P2 | H39: 1. Có dữ liệu đã áp dụng 1 bộ lọc. | I39: 1) Nhấn “Tải xuống” → chọn .xlsx; 2) Mở file kiểm tra; 3) Xóa lọc → export lại; 4) So sánh 2 file | J39: (i) Logic: không áp dụng. (ii) UI: Hộp thoại export hoạt động; file sinh thành công. (iii) OT.01: không áp dụng. (iv) File: Lần 1 theo bộ lọc; lần 2 toàn bộ. | K39: II.5.1.1.1 | L39: UI-FUNC.06 | M39: UI-EXPORT-BASIC | U39: =IF(R25<>"", R25, O25)
A40: PR01-UI-07-ADDCODE-038 | B40: PR01 | C40: UI - Thêm code phí | D40: Điều hướng “Thêm code phí” từ SPDV cấp cuối mở đúng form khởi tạo | E40: Happy | F40: Regression | G40: P2 | H40: 1. Có SPDV cấp cuối đã duyệt Maker đăng nhập. | I40: 1) Tại SPDV cuối → nhấn “Thêm code phí”; 2) Quan sát form khởi tạo; 3) Quay lại | J40: (i) Logic: không áp dụng. (ii) UI: Form Add Code phí mở đúng ngữ cảnh SPDV cuối. (iii) OT.01: không áp dụng. (iv) Data: không đổi. | K40: II.5.1.1.1 | L40: UI-FUNC.07 | M40: UI-ADDCODE-NAV | N40: UI-only; BR Code phí nằm ngoài phạm vi URD-đoạn này | U40: =IF(R26<>"", R26, O26)
A41: PR01-UI-META-039 | B41: PR01 | C41: UI - Lưới/Meta | D41: Cột “Ngày tạo/Người tạo” hiển thị đúng định dạng & giá trị | E41: Happy | F41: Regression | G41: P3 | H41: 1. Có dữ liệu nhiều bản ghi. | I41: 1) Mở lưới; 2) Bật hiển thị cột Ngày tạo/Người tạo; 3) Quan sát định dạng & giá trị | J41: (i) Logic: không áp dụng. (ii) UI: Ngày định dạng chuẩn; Người tạo hiển thị đúng. (iii) OT.01: không áp dụng. (iv) Data: khớp DB/audit. | K41: II.5.1.1.2/BR_11; II.5.1.1.2/BR_12; II.5.1.1.3/BR_17; II.5.1.1.3/BR_18 | L41: UI-FUNC.05 | M41: UI-META-DISPLAY | N41: UI chỉ kiểm hiển thị; logic auto đã có BR11/12 & BR17/18 | U41: =IF(R27<>"", R27, O27)
...

Sheet II.5.1.1.3
A1: TEST CASES — II.5.1.1.3. Thêm mới Sản phẩm,
A2: TC_ID | B2: Module | C2: Feature | D2: Title | E2: Type | F2: Category | G2: Priority | H2: Precondition | I2: Steps | J2: Expected | K2: URD_Ref | L2: BR_Ref | M2: Trace_ID | N2: Note | O2: Status R1 | P2: Tester R1 | Q2: Date R1 | R2: Status R2 | S2: Tester R2 | T2: Date R2 | U2: Final Status
A3: PR01D-BR01-NEG-001 | B3: PR01 | C3: SPDV chi tiết - Thêm mới | D3: Thiếu trường bắt buộc khi thêm SPDV chi tiết → chặn lưu | E3: Negative | F3: Smoke | G3: P1 | H3: 1. Có NV (SPDV cấp đã duyệt Maker đăng nhập ngày T. | I3: 1) Tại bản ghi NV cha → nhấn “+”; 2) Bỏ trống 1+ trường bắt buộc (*); 3) Nhấn “Xác nhận” | J3: (i) Logic: Thiếu mandatory → từ chối lưu. (ii) UI: Highlight trường lỗi/toast lỗi; form không đóng. (iii) OT.01: không sinh tác vụ. (iv) Data: Không tạo bản ghi/audit. | K3: II.5.1.1.3/BR_01 | L3: BR_01 | M3: BR01-SPDV-REQ | U3: =IF(R3<>"", R3, O3)
A4: PR01D-BR02-NEG-002 | B4: PR01 | C4: SPDV chi tiết - Thêm mới | D4: Đóng/Hủy form Thêm SPDV chi tiết → không lưu dữ liệu | E4: Negative | F4: Regression | G4: P2 | H4: 1. Form Thêm SPDV chi tiết đang mở đã nhập vài trường. | I4: 1) Nhập vài trường; 2) Nhấn “Đóng/Hủy”; 3) Xác nhận nếu có; 4) Về lưới tìm theo dữ liệu vừa nhập | J4: (i) Logic: Đóng/Hủy → không lưu. (ii) UI: Form đóng, không có toast thành công. (iii) OT.01: không áp dụng. (iv) Data: Không phát sinh CREATE/audit. | K4: II.5.1.1.3/BR_02 | L4: BR_02 | M4: BR02-SPDV-CLOSE | U4: =IF(R4<>"", R4, O4)
A5: PR01D-BR03-HAPPY-003 | B5: PR01 | C5: SPDV chi tiết - Hiển thị danh sách | D5: Chỉ hiển thị bản ghi SPDV chi tiết đã được Checker phê duyệt | E5: Happy | F5: Smoke | G5: P1 | H5: 1. Có 1 SPDV chi tiết vừa tạo (Chờ duyệt). | I5: 1) Về lưới Danh mục SPDV; 2) Lọc theo Tên/Mã SPDV chi tiết; 3) Duyệt tác vụ; 4) Refresh lưới | J5: (i) Logic: Pending → không hiển thị; sau duyệt → hiển thị. (ii) UI: Lưới phản ánh đúng. (iii) OT.01: Có tác vụ/APPROVE ghi nhận. (iv) Data: Trạng thái chuyển ‘Đã duyệt’. | K5: II.5.1.1.3/BR_03 | L5: BR_03 | M5: BR03-SPDV-LIST-VIS | U5: =IF(R5<>"", R5, O5)
A6: PR01D-BR04-HAPPY-004 | B6: PR01 | C6: SPDV chi tiết - Auto code | D6: Mã SPDV chi tiết = [Mã cha] + 2 số tự tăng; duy nhất | E6: Happy | F6: Smoke | G6: P1 | H6: 1. NV cha mã 06 đã duyệt Maker đăng nhập. | I6: 1) Tại 06 → bấm “+” tạo SPDV chi tiết A → “Xác nhận”; 2) Tạo tiếp SPDV chi tiết B → “Xác nhận”; 3) Mở chi tiết A/B xem trường Mã | J6: (i) Logic: Mã sinh 0601, 0602…; duy nhất. (ii) UI: Trường Mã read‑only. (iii) OT.01: Hai bản ghi ở ‘Chờ duyệt’. (iv) Data: Audit CREATE có mã auto. | K6: II.5.1.1.3/BR_04; II.5.1.1.3/BR_05 | L6: BR_04;BR_05 | M6: BR04-SPDV-AUTOCODE | U6: =IF(R6<>"", R6, O6)
A7: PR01D-BR04-BOUND-005 | B7: PR01 | C7: SPDV chi tiết - Auto code | D7: Tạo bản ghi thứ 100 dưới cùng 1 cha (… 0600) → vượt ngưỡng 99 → chặn | E7: Boundary | F7: Regression | G7: P2 | H7: 1. Dưới mã cha 06 đã có 99 bản chi tiết (0601. | I7: 1) Thử tạo thêm bản chi tiết thứ 100; 2) “Xác nhận” | J7: (i) Logic: Không cấp mã >99 → chặn. (ii) UI: Thông báo rõ ngưỡng. (iii) OT.01: không áp dụng. (iv) Data: Không tạo bản ghi. | K7: II.5.1.1.3/BR_04 | L7: BR_04 | M7: BR04-SPDV-OVER99 | U7: =IF(R7<>"", R7, O7)
A8: PR01D-BR05-HAPPY-006 | B8: PR01 | C8: SPDV chi tiết - Field control | D8: Trường Mã SPDV chi tiết không cho phép chỉnh sửa | E8: Happy | F8: Regression | G8: P3 | H8: 1. Có SPDV chi tiết trạng thái Chờ duyệt hoặc Đã duyệt. | I8: 1) Mở chi tiết → “Sửa”; 2) Thử thay đổi trường Mã; 3) Lưu | J8: (i) Logic: Không cho sửa Mã. (ii) UI: Ô Mã disabled/read‑only. (iii) OT.01: Nếu chỉ sửa Mã → chặn; sửa trường khác → sinh tác vụ. (iv) Data: Mã giữ nguyên. | K8: II.5.1.1.3/BR_05 | L8: BR_05 | M8: BR05-SPDV-CODE-RO | U8: =IF(R8<>"", R8, O8)
A9: PR01D-BR06-HAPPY-007 | B9: PR01 | C9: SPDV chi tiết - Ngữ cảnh cha | D9: “Cấp SPDV liền trước” hiển thị đúng “Mã - Tên” cấp cha khi bấm “+” | E9: Happy | F9: Regression | G9: P3 | H9: 1. Có bản ghi cha đã duyệt Maker đăng nhập. | I9: 1) Ở bản ghi cha → bấm “+”; 2) Quan sát trường “Cấp SPDV liền trước” | J9: (i) Logic: Lấy đúng Mã‑Tên cha. (ii) UI: Label hiển thị chính xác. (iii) OT.01: không áp dụng. (iv) Data: Không thay đổi. | K9: II.5.1.1.3/BR_06 | L9: BR_06 | M9: BR06-SPDV-PARENTCTX | U9: =IF(R9<>"", R9, O9)
A10: PR01D-BR07-BOUND-008 | B10: PR01 | C10: SPDV chi tiết - Giới hạn cấp | D10: Không cho phép tạo cấp vượt PRODUCT_LEVEL | E10: Boundary | F10: Regression | G10: P2 | H10: 1. PRODUCT_LEVEL = n (vd n=5) cây đang ở cấp n. | I10: 1) Ở cấp n → bấm “+”; 2) Quan sát cảnh báo; 3) Thử ‘Xác nhận’ | J10: (i) Logic: Vượt cấp tối đa → chặn. (ii) UI: Vùng thêm con disabled/hiển thị cảnh báo. (iii) OT.01: không áp dụng. (iv) Data: Không tạo. | K10: II.5.1.1.3/BR_07; II.5.1.1.3/BR_10 | L10: BR_07;BR_10 | M10: BR07-SPDV-MAXLEVEL | U10: =IF(R10<>"", R10, O10)
A11: PR01D-BR08-NEG-009 | B11: PR01 | C11: SPDV chi tiết - Quan hệ cha | D11: Bắt buộc khai báo đủ n−1 cấp cha trước khi khai báo cấp cuối n | E11: Negative | F11: Smoke | G11: P1 | H11: 1. PRODUCT_LEVEL=n còn thiếu 1 cấp cha ở giữa. | I11: 1) Cố tạo SPDV cấp n khi thiếu cấp cha; 2) Nhấn “Xác nhận” | J11: (i) Logic: Thiếu cấp cha → chặn. (ii) UI: Nêu rõ cấp thiếu. (iii) OT.01: không áp dụng. (iv) Data: Không tạo. | K11: II.5.1.1.3/BR_08 | L11: BR_08 | M11: BR08-SPDV-MISS-PARENT | U11: =IF(R11<>"", R11, O11)
A12: PR01D-BR09-HAPPY-010 | B12: PR01 | C12: SPDV chi tiết - Cảnh báo cấp cuối | D12: Hiển thị nhãn “Đây là cấp cuối cùng…” khi khai báo cấp n | E12: Happy | F12: Regression | G12: P3 | H12: 1. Đang thao tác ở cấp n. | I12: 1) Mở form ở cấp n; 2) Quan sát thông tin cảnh báo cấp cuối | J12: (i) Logic: Hệ thống hiển thị đúng thông điệp. (ii) UI: Text cảnh báo hiển thị. (iii) OT.01: không áp dụng. (iv) Data: Không đổi. | K12: II.5.1.1.3/BR_09 | L12: BR_09 | M12: BR09-SPDV-LASTLEVEL | U12: =IF(R12<>"", R12, O12)
A13: PR01D-BR10-NEG-011 | B13: PR01 | C13: SPDV chi tiết - Cấm thêm con ở cấp cuối | D13: Tại bản ghi cấp n không thể thêm mới SPDV cấp con | E13: Negative | F13: Regression | G13: P2 | H13: 1. Có SPDV cấp n Maker đăng nhập. | I13: 1) Vào bản ghi cấp n; 2) Kiểm tra sự hiện diện/enable của nút “+” | J13: (i) Logic: Không cho phép thêm con tại cấp n. (ii) UI: Nút “+” ẩn/disabled. (iii) OT.01: không áp dụng. (iv) Data: Không phát sinh bản ghi. | K13: II.5.1.1.3/BR_10 | L13: BR_10 | M13: BR10-SPDV-NO-CHILD | U13: =IF(R13<>"", R13, O13)
A14: PR01D-BR11-NEG-012 | B14: PR01 | C14: SPDV chi tiết - Hiệu lực | D14: Ngày hiệu lực hoặc Ngày hết hiệu lực ở quá khứ → chặn | E14: Negative | F14: Smoke | G14: P1 | H14: 1. Form Thêm mới SPDV chi tiết mở ngày T. | I14: 1) Đặt Ngày hiệu lực < T → “Xác nhận”; 2) Đặt Ngày hết hiệu lực < T → “Xác nhận” | J14: (i) Logic: Không cho ngày quá khứ. (ii) UI: Lỗi tại trường ngày. (iii) OT.01: không áp dụng. (iv) Data: Không lưu. | K14: II.5.1.1.3/BR_11 | L14: BR_11 | M14: BR11-SPDV-DATEPAST | U14: =IF(R14<>"", R14, O14)
... A16: PR01D-BR13-NEG-014 | B16: PR01 | C16: SPDV chi tiết - Quan hệ hiệu lực | D16: Hiệu lực con phải nằm trong khoảng hiệu lực cha → vi phạm bị chặn | E16: Negative | F16: Smoke | G16: P1 | H16: 1. Cha hiệu lực [T1–T2] Maker đăng nhập. | I16: 1) Tạo con với [T1' < T1] hoặc [T2' > T2]; 2) “Xác nhận” | J16: (i) Logic: Con vượt ngoài cha → từ chối. (ii) UI: Thông báo nêu rõ quan hệ cha–con. (iii) OT.01: không áp dụng. (iv) Data: Không lưu. | K16: II.5.1.1.3/BR_13 | L16: BR_13 | M16: BR13-SPDV-CHILD-INHERIT | U16: =IF(R16<>"", R16, O16)
A17: PR01D-BR14-HAPPY-015 | B17: PR01 | C17: SPDV chi tiết - Đổi trạng thái | D17: Đổi trạng thái qua cập nhật “Ngày hết hiệu lực” (Versioning C) | E17: Happy | F17: Regression | G17: P2 | H17: 1. Có SPDV chi tiết đang Đang hoạt động Maker có quyền sửa. | I17: 1) Mở chi tiết → “Sửa”; 2) Đặt Ngày hết hiệu lực = T; 3) “Xác nhận” (sinh tác vụ); 4) Checker duyệt; 5) Kiểm tra trạng thái | J17: (i) Logic: Update in‑place; hết hiệu lực → Ngưng hoạt động; có thể đổi ngược bằng hiệu lực mới. (ii) UI: Trạng thái đổi sau duyệt. (iii) OT.01: UPDATE + APPROVE. (iv) Data: Không tạo version record mới. | K17: II.5.1.1.3/BR_14 | L17: BR_14 | M17: BR14-SPDV-STATE-CHANGE | N17: Theo bối cảnh: Versioning C | U17: =IF(R17<>"", R17, O17)
A18: PR01D-BR15-HAPPY-016 | B18: PR01 | C18: SPDV chi tiết - Hiển thị | D18: Chưa duyệt không hiển thị trên lưới Danh mục SPDV | E18: Happy | F18: Smoke | G18: P1 | H18: 1. Vừa tạo SPDV chi tiết trạng thái Chờ duyệt. | I18: 1) Về lưới Danh mục SPDV; 2) Lọc theo Tên/Mã vừa tạo | J18: (i) Logic: Pending → không hiển thị. (ii) UI: Không có kết quả. (iii) OT.01: Có tác vụ chờ duyệt. (iv) Data: Trạng thái Chờ duyệt lưu DB. | K18: II.5.1.1.3/BR_15; II.5.1.1.3/BR_16 | L18: BR_15;BR_16 | M18: BR15-SPDV-NOTSHOW | U18: =IF(R18<>"", R18, O18)
A19: PR01D-BR16-HAPPY-017 | B19: PR01 | C19: SPDV chi tiết - Tác vụ | D19: Sau khi lưu → sinh tác vụ “Chờ duyệt” | E19: Happy | F19: Smoke | G19: P1 | H19: 1. Vừa lưu SPDV chi tiết. | I19: 1) Mở “Tác vụ chờ duyệt”; 2) Tìm theo Mã/Tên SPDV chi tiết | J19: (i) Logic: Tác vụ phải tồn tại. (ii) UI: Hàng tác vụ xuất hiện; có nút Duyệt/Từ chối theo vai. (iii) OT.01: Ghi nhận tạo tác vụ. (iv) Data: Audit TASK. | K19: II.5.1.1.3/BR_16 | L19: BR_16 | M19: BR16-SPDV-TASK | U19: =IF(R19<>"", R19, O19)
A20: PR01D-BR17-HAPPY-018 | B20: PR01 | C20: SPDV chi tiết - Metadata | D20: “Ngày tạo” tự sinh đúng định dạng | E20: Happy | F20: Regression | G20: P3 | H20: 1. Có SPDV chi tiết vừa tạo. | I20: 1) Mở chi tiết; 2) Quan sát ‘Ngày tạo’ | J20: (i) Logic: Hệ thống tự sinh theo chuẩn. (ii) UI: YYYY‑MM‑DD HH:MM:SS. (iii) OT.01: không áp dụng. (iv) Data: Audit time khớp. | K20: II.5.1.1.3/BR_17 | L20: BR_17 | M20: BR17-SPDV-CREATEDAT | U20: =IF(R20<>"", R20, O20)
A21: PR01D-BR18-HAPPY-019 | B21: PR01 | C21: SPDV chi tiết - Metadata | D21: “Người tạo” = username Maker | E21: Happy | F21: Regression | G21: P3 | H21: 1. Có SPDV chi tiết do Maker tạo. | I21: 1) Mở chi tiết; 2) Quan sát ‘Người tạo’ | J21: (i) Logic: Lưu đúng username. (ii) UI: Hiển thị chính xác. (iii) OT.01: không áp dụng. (iv) Data: Audit CREATE ghi user. | K21: II.5.1.1.3/BR_18 | L21: BR_18 | M21: BR18-SPDV-CREATEDBY | U21: =IF(R21<>"", R21, O21)
A22: PR01D-FLOW-OT01-HAPPY-020 | B22: PR01 | C22: SPDV chi tiết - OT.01 Phê duyệt | D22: Checker phê duyệt → bản ghi hiển thị trên lưới và khả dụng | E22: Happy | F22: Smoke | G22: P1 | H22: 1. Có 1 SPDV chi tiết ở Chờ duyệt. | I22: 1) Checker mở ‘Tác vụ chờ duyệt’; 2) Mở tác vụ → “Duyệt”; 3) Về lưới kiểm tra | J22: (i) Logic: Trạng thái chuyển ‘Đã duyệt’, bản ghi khả dụng. (ii) UI: Lưới hiển thị bản ghi. (iii) OT.01: Audit APPROVE (user, timestamp). (iv) Data: Lưu trạng thái & log. | K22: II.5.1.1.3/BR_16 | L22: BR_16 | M22: FLOW-APPROVE-SPDV | U22: =IF(R22<>"", R22, O22)
A23: PR01D-FLOW-OT01-NEG-021 | B23: PR01 | C23: SPDV chi tiết - OT.01 Từ chối | D23: Checker từ chối → không hiển thị trên lưới | E23: Negative | F23: Smoke | G23: P1 | H23: 1. Có 1 SPDV chi tiết ở Chờ duyệt. | I23: 1) Checker mở ‘Tác vụ chờ duyệt’; 2) “Từ chối”, nhập lý do; 3) Về lưới kiểm tra | J23: (i) Logic: Từ chối → không hiển thị/không áp dụng. (ii) UI: Lý do hiển thị tại lịch sử. (iii) OT.01: Audit REJECT. (iv) Data: Trạng thái ‘Từ chối’ lưu DB. | K23: II.5.1.1.3/BR_15; II.5.1.1.3/BR_16 | L23: BR_15;BR_16 | M23: FLOW-REJECT-SPDV | U23: =IF(R23<>"", R23, O23)
A24: PR01D-FLOW-EFF-HAPPY-022 | B24: PR01 | C24: SPDV chi tiết - Sửa hiệu lực (Versioning C) | D24: Sửa ngày hiệu lực hợp lệ ở mọi trạng thái → update in‑place sau duyệt | E24: Happy | F24: Regression | G24: P2 | H24: 1. Có SPDV chi tiết ‘Đã duyệt’ Maker có quyền sửa. | I24: 1) Maker mở chi tiết → “Sửa”; 2) Nhập [T1'–T2'] hợp lệ (không quá khứ/không vượt cha/không end<start); 3) “Xác nhận” (sinh tác vụ); 4) Checker duyệt; 5) Kiểm tra hiệu lực mới | J24: (i) Logic: Versioning C: cập nhật in‑place; không tạo version record mới. (ii) UI: Tác vụ hiển thị; sau duyệt, hiệu lực mới hiển thị. (iii) OT.01: UPDATE + APPROVE. (iv) Data: Record hiện hữu được cập nhật. | K24: II.5.1.1.3; (Bối cảnh dự án) | M24: FLOW-EFF-VALID-SPDV | N24: Áp dụng rule hiệu lực chung dự án | U24: =IF(R24<>"", R24, O24)
A25: PR01D-FLOW-EFF-NEG-023 | B25: PR01 | C25: SPDV chi tiết - Sửa hiệu lực (Versioning C) | D25: Sửa hiệu lực end<start/ra quá khứ/vượt cha → chặn & không tạo tác vụ | E25: Negative | F25: Regression | G25: P2 | H25: 1. Có SPDV chi tiết ở trạng thái bất kỳ Maker mở Sửa. | I25: 1) Nhập Ngày hết < Ngày hiệu lực; 2) Hoặc đặt ngày quá khứ; 3) Hoặc set hiệu lực vượt [T1–T2] của cha; 4) “Xác nhận” | J25: (i) Logic: Vi phạm logic hiệu lực → chặn. (ii) UI: Thông báo lỗi cụ thể. (iii) OT.01: Không sinh tác vụ. (iv) Data: Không thay đổi. | K25: II.5.1.1.3/BR_11; II.5.1.1.3/BR_13 | M25: FLOW-EFF-INVALID-SPDV | U25: =IF(R25<>"", R25, O25)
A26: PR01D-UI-01-OPEN-024 | B26: PR01 | C26: SPDV chi tiết - UI Thêm mới | D26: Mở form Thêm SPDV chi tiết từ cấp cha; hiển thị đủ vùng & control | E26: Happy | F26: Regression | G26: P3 | H26: 1. Có SPDV cha đã duyệt Maker đăng nhập. | I26: 1) Tại bản ghi cha → bấm “+”; 2) Quan sát các vùng thông tin & nút (Lưu/Xác nhận/Đóng) | J26: (i) Logic: không áp dụng. (ii) UI: Vùng/field/nút hiển thị đúng & enable theo ngữ cảnh. (iii) OT.01: không áp dụng. (iv) Data: Không đổi. | K26: II.5.1.1.3/Step‑1~2 | L26: UI-FUNC.01 | M26: UI-OPEN-ADD-SPDV | N26: UI-only; không lặp BR | U26: =IF(R26<>"", R26, O26)
A27: PR01D-UI-02-RO-025 | B27: PR01 | C27: SPDV chi tiết - UI Xem | D27: Xem chi tiết SPDV chi tiết ở chế độ read‑only | E27: Happy | F27: Regression | G27: P3 | H27: 1. Có dữ liệu SPDV chi tiết ở bất kỳ trạng thái. | I27: 1) Chọn bản ghi → “Xem”; 2) Quan sát trạng thái field | J27: (i) Logic: không áp dụng. (ii) UI: Chỉ xem; không cho chỉnh sửa. (iii) OT.01: không áp dụng. (iv) Data: Không đổi. | K27: II.5.1.1.3 | L27: UI-FUNC.03 | M27: UI-VIEW-RO-SPDV | U27: =IF(R27<>"", R27, O27)
A28: PR01D-UI-03-EDITNAV-026 | B28: PR01 | C28: SPDV chi tiết - UI Sửa | D28: Điều hướng Sửa → Lưu → quay lại lưới vẫn giữ giá trị đã lưu | E28: Happy | F28: Regression | G28: P3 | H28: 1. Có SPDV chi tiết Maker có quyền sửa. | I28: 1) Tại lưới chọn bản ghi → “Sửa”; 2) Thay đổi Mô tả nhỏ → “Xác nhận”; 3) Quay lại lưới → mở lại chi tiết kiểm tra | J28: (i) Logic: không áp dụng. (ii) UI: Giá trị đã lưu hiển thị đúng; điều hướng mượt. (iii) OT.01: Nếu thay đổi thuộc phạm vi duyệt → sinh tác vụ. (iv) Data: Audit UPDATE ghi trường thay đổi. | K28: II.5.1.1.3 | L28: UI-FUNC.04 | M28: UI-EDIT-NAV-SPDV | N28: Không test rule hiệu lực (đã ở Flow) | U28: =IF(R28<>"", R28, O28)
A29: PR01D-UI-04-FILTER-027 | B29: PR01 | C29: SPDV chi tiết - UI Lọc | D29: Tìm kiếm theo Tên/Mã/Trạng thái; “Xóa lọc” khôi phục lưới | E29: Happy | F29: Regression | G29: P2 | H29: 1. Có nhiều bản ghi SPDV chi tiết. | I29: 1) Lọc theo Tên; 2) Lọc theo Mã; 3) Lọc theo Trạng thái; 4) Nhấn “Xóa lọc” | J29: (i) Logic: không áp dụng. (ii) UI: Bộ lọc trả về đúng kết quả; Xóa lọc khôi phục lưới. (iii) OT.01: không áp dụng. (iv) Data: Không đổi. | K29: II.5.1.1.3 | L29: UI-FUNC.05 | M29: UI-FILTER-SPDV | U29: =IF(R29<>"", R29, O29)
A30: PR01D-UI-05-EXPORT-028 | B30: PR01 | C30: SPDV chi tiết - UI Tải xuống | D30: Export dữ liệu lưới ra .xlsx (theo lọc & toàn bộ) | E30: Happy | F30: Regression | G30: P2 | H30: 1. Có dữ liệu đang áp dụng 1 bộ lọc. | I30: 1) “Tải xuống” → chọn .xlsx; 2) Mở file kiểm tra; 3) Xóa lọc → export lại; 4) So sánh 2 file | J30: (i) Logic: không áp dụng. (ii) UI: Export hoạt động; thông báo thành công. (iii) OT.01: không áp dụng. (iv) File: Lần 1 theo bộ lọc; lần 2 toàn bộ. | K30: II.5.1.1.3 | L30: UI-FUNC.06 | M30: UI-EXPORT-SPDV | U30: =IF(R30<>"", R30, O30)
A31: PR01D-UI-06-META-029 | B31: PR01 | C31: SPDV chi tiết - UI Lưới/Meta | D31: Cột “Ngày tạo/Người tạo” hiển thị đúng định dạng/giá trị | E31: Happy | F31: Regression | G31: P3 | H31: 1. Có dữ liệu đa trạng thái. | I31: 1) Bật hiển thị cột ‘Ngày tạo/Người tạo’; 2) Quan sát định dạng & giá trị | J31: (i) Logic: không áp dụng. (ii) UI: YYYY‑MM‑DD HH:MM:SS; Người tạo đúng username. (iii) OT.01: không áp dụng. (iv) Data: Khớp DB/audit. | K31: II.5.1.1.3/BR_17; II.5.1.1.3/BR_18 | L31: UI-FUNC.05 | M31: UI-META-DISPLAY-SPDV | N31: UI kiểm hiển thị; logic auto đã có BR17/18 | U31: =IF(R31<>"", R31, O31)
A32: PR01D-NOTE-ONLY-030 | B32: PR01 | C32: Note only | D32: ĐÃ COVER “chưa duyệt không hiển thị” & “tác vụ chờ duyệt” | E32: Note only | F32: - | G32: P3 | I32: - | J32: ĐÃ COVER ở PR01D-BR15-HAPPY-016 và PR01D-BR16-HAPPY-017 (URD_Ref II.5.1.1.3/BR_15; BR_16) | K32: II.5.1.1.3/BR_15; II.5.1.1.3/BR_16 | L32: - | M32: DEDUP-NOTSHOW-TASK
A33: PR01-BR13-BOU-031 | B33: PR01 | C33: Hiệu lực Cha-Con | D33: BR_13: Hiệu lực con khớp 100% với hiệu lực cha (Biên cận trên/dưới) | E33: Boundary | F33: Regression | G33: P1 | H33: 1. SPDV Cha có hiệu lực: [2026-01-01 - 2026-12-31]. | I33: 1. Thực hiện thêm mới SPDV con. 2. Nhập Ngày hiệu lực = 2026-01- 01. 3. Nhập Ngày hết hiệu lực = 2026-12- 31. 4. Nhấn Xác nhận. | J33: (i) Logic: Hệ thống chấp nhận vì nằm trong khoảng [T1-T2] của cha (bao gồm cả biên). (ii) UI: Không báo lỗi vượt kỳ cha. (iii) Trạng thái: Chờ duyệt. (iv) Khác: N/A | K33: BR Code: BR_13 | L33: BR_13 | M33: BR13-BOU-MATCH | N33: Bổ sung GAPs review. | U33: =IF(R32<>"", R32, O32)
A34: PR01-BR04-HAP-032 | B34: PR01 | C34: Mã tự sinh | D34: BR_04: Verify Mã SPDV con hiển thị đúng format [Mã cha][01-99] | E34: HappyPath | F34: Smoke | G34: P1 | H34: 1. Mã SPDV cha = 06. | I34: 1. Tại lưới danh sách, nhấn '+' tại dòng mã 06. 2. Quan sát trường 'Mã SPDV chi tiết' trên Form. | J34: (i) Logic: Mã tự sinh đúng nguyên tắc ghép chuỗi. (ii) UI: Mã hiển thị là 0601 (nếu là con đầu tiên) hoặc 06xx. (iii) Trạng thái: N/A. (iv) Khác: N/A | K34: BR Code: BR_04 | L34: BR_04 | M34: BR04-CODE-FORMAT | N34: Bổ sung GAPs review. | U34: =IF(R33<>"", R33, O33)
